Workbook

Sheet CONFIG
B1: ⚙️ KONFIGURASI SISTEM ABSENSI
B3: Nama Sekolah | C3: SMP Plus YPP Darussurur
B4: Tanggal Mulai Periode | C4: 46106
B5: Tanggal Akhir Periode | C5: 46136
B6: Petugas / TTD | C6: Wilman Juniansyah, S.Pd.
B7: Kota | C7: Cimahi
B8: Keterangan Ekstra | C8: Periode 25 Maret - 24 April 2026
B10: LEGENDA WARNA STATUS
B11: Mengajar
B12: Sakit
B13: Izin
B14: Dinas Keluar Sekolah
B15: Tanpa Keterangan
B16: Libur Tanggal Merah
B17: Libur (umum/sekolah)
B18: Minggu / Tidak Dijadwalkan
B19: Hari Tidak Ada Jadwal

Sheet DATA_GURU
B1: MASTER DATA GURU — SMP Plus YPP Darussurur
B2: No | C2: Nama Guru | D2: Mata Pelajaran
B3: 1 | C3: Dewi Andriani, S.Pd | D3: Matematika
B4: 2 | C4: Wiwin Nitasari, S.Pd | D4: PKN
B5: 3 | C5: Indra Kurniawan, A.Md | D5: Prakarya - TIK
B6: 4 | C6: Siti Satriah, S.Pd | D6: B. Inggris
B7: 5 | C7: Klidia Nurwulan, S.Pd | D7: B. Indonesia
B8: 6 | C8: Putri Megawati, S.Pd | D8: PJOK
B9: 7 | C9: Dani Ramdhani, S.Pd | D9: B. Inggris
B10: 8 | C10: Shafa Padilah S. S.Pd | D10: B. Indonesia
B11: 9 | C11: Imam Hasbulloh, S.Pd | D11: Matematika
B12: 10 | C12: Muhamad Aldiansyah | D12: B. Inggris
B13: 11 | C13: M. Fadilah Abdurahman | D13: Seni Budaya
B14: 12 | C14: Ahmad Yusup | D14: TIK
... B22: 20 | C22: Abdullah Nurrachman Soleh, S.Pd | D22: PJOK

Sheet DATA_JAM_PELAJARAN
B1: DATA JAM PELAJARAN — SMP Plus YPP Darussurur
E2: Jam Pelajaran per Hari
B3: No | C3: Nama Guru | D3: Mata Pelajaran | E3: Senin | F3: Selasa | G3: Rabu | H3: Kamis | I3: Jumat | J3: Sabtu | K3: Total/Minggu
B4: 1 | C4: Dewi Andriani, S.Pd | D4: Matematika | E4: 0 | F4: 4 | G4: 0 | H4: 0 | I4: 6 | J4: 0 | K4: =SUM(E4:J4) -> 10
B5: 2 | C5: Wiwin Nitasari, S.Pd | D5: PKN | E5: 9 | F5: 9 | G5: 6 | H5: 0 | I5: 9 | J5: 0 | K5: =SUM(E5:J5) -> 33
B6: 3 | C6: Indra Kurniawan, A.Md | D6: Prakarya - TIK | E6: 4 | F6: 6 | G6: 0 | H6: 4 | I6: 0 | J6: 0 | K6: =SUM(E6:J6) -> 14
B7: 4 | C7: Siti Satriah, S.Pd | D7: B. Inggris | E7: 4 | F7: 4 | G7: 0 | H7: 0 | I7: 8 | J7: 0 | K7: =SUM(E7:J7) -> 16
B8: 5 | C8: Klidia Nurwulan, S.Pd | D8: B. Indonesia | E8: 7 | F8: 7 | G8: 0 | H8: 7 | I8: 9 | J8: 0 | K8: =SUM(E8:J8) -> 30
B9: 6 | C9: Putri Megawati, S.Pd | D9: PJOK | E9: 0 | F9: 6 | G9: 3 | H9: 0 | I9: 6 | J9: 0 | K9: =SUM(E9:J9) -> 15
B10: 7 | C10: Dani Ramdhani, S.Pd | D10: B. Inggris | E10: 0 | F10: 4 | G10: 5 | H10: 0 | I10: 3 | J10: 0 | K10: =SUM(E10:J10) -> 12
B11: 8 | C11: Shafa Padilah S. S.Pd | D11: B. Indonesia | E11: 8 | F11: 6 | G11: 5 | H11: 0 | I11: 6 | J11: 0 | K11: =SUM(E11:J11) -> 25
B12: 9 | C12: Imam Hasbulloh, S.Pd | D12: Matematika | E12: 7 | F12: 7 | G12: 6 | H12: 6 | I12: 9 | J12: 0 | K12: =SUM(E12:J12) -> 35
B13: 10 | C13: Muhamad Aldiansyah | D13: B. Inggris | E13: 4 | F13: 2 | G13: 4 | H13: 6 | I13: 0 | J13: 0 | K13: =SUM(E13:J13) -> 16
B14: 11 | C14: M. Fadilah Abdurahman | D14: Seni Budaya | E14: 0 | F14: 3 | G14: 6 | H14: 3 | I14: 4 | J14: 0 | K14: =SUM(E14:J14) -> 16
B15: 12 | C15: Ahmad Yusup | D15: TIK | E15: 4 | F15: 0 | G15: 4 | H15: 4 | I15: 2 | J15: 0 | K15: =SUM(E15:J15) -> 14
... B23: 20 | C23: Abdullah Nurrachman Soleh, S.Pd | D23: PJOK | E23: 6 | F23: 3 | G23: 0 | H23: 6 | I23: 3 | J23: 0 | K23: =SUM(E23:J23) -> 18
B24: TOTAL JAM / MINGGU | E24: =SUM(E4:E23) -> 77 | F24: =SUM(F4:F23) -> 77 | G24: =SUM(G4:G23) -> 77 | H24: =SUM(H4:H23) -> 77 | I24: =SUM(I4:I23) -> 99 | J24: =SUM(J4:J23) -> 0 | K24: =SUM(K4:K23) -> 407

Sheet ABSENSI
B1: =CONFIG!C3&" · ABSENSI GURU · "&TEXT(CONFIG!C4,"DD MMMM YYYY")&" s.d. "&TEXT(CONFIG!C5,"DD MMMM YYYY") -> SMP Plus YPP Darussurur · ABSENSI GURU · 25 March 2026 s.d. 24 April 2026
B2: No | C2: Nama Guru & Mata Pelajaran | D2: =CONFIG!C4 -> 46106 | E2: =IF(D2="","",IF(D2+1<=CONFIG!$C$5,D2+1,"")) -> 46107 | F2: =IF(E2="","",IF(E2+1<=CONFIG!$C$5,E2+1,"")) -> 46108 | G2: =IF(F2="","",IF(F2+1<=CONFIG!$C$5,F2+1,"")) -> 46109 | H2: =IF(G2="","",IF(G2+1<=CONFIG!$C$5,G2+1,"")) -> 46110 | I2: =IF(H2="","",IF(H2+1<=CONFIG!$C$5,H2+1,"")) -> 46111 | J2: =IF(I2="","",IF(I2+1<=CONFIG!$C$5,I2+1,"")) -> 46112 | K2: =IF(J2="","",IF(J2+1<=CONFIG!$C$5,J2+1,"")) -> 46113 | L2: =IF(K2="","",IF(K2+1<=CONFIG!$C$5,K2+1,"")) -> 46114 | ... AQ2: =IF(AP2="","",IF(AP2+1<=CONFIG!$C$5,AP2+1,""))
C3: MATA PELAJARAN | D3: =IF(D2="","",CHOOSE(WEEKDAY(D2,2),"Senin","Selasa","Rabu","Kamis","Jumat","Sabtu","Minggu")) -> Rabu | E3: =IF(E2="","",CHOOSE(WEEKDAY(E2,2),"Senin","Selasa","Rabu","Kamis","Jumat","Sabtu","Minggu")) -> Kamis | F3: =IF(F2="","",CHOOSE(WEEKDAY(F2,2),"Senin","Selasa","Rabu","Kamis","Jumat","Sabtu","Minggu")) -> Jumat | G3: =IF(G2="","",CHOOSE(WEEKDAY(G2,2),"Senin","Selasa","Rabu","Kamis","Jumat","Sabtu","Minggu")) -> Sabtu | H3: =IF(H2="","",CHOOSE(WEEKDAY(H2,2),"Senin","Selasa","Rabu","Kamis","Jumat","Sabtu","Minggu")) -> Minggu | I3: =IF(I2="","",CHOOSE(WEEKDAY(I2,2),"Senin","Selasa","Rabu","Kamis","Jumat","Sabtu","Minggu")) -> Senin | J3: =IF(J2="","",CHOOSE(WEEKDAY(J2,2),"Senin","Selasa","Rabu","Kamis","Jumat","Sabtu","Minggu")) -> Selasa | K3: =IF(K2="","",CHOOSE(WEEKDAY(K2,2),"Senin","Selasa","Rabu","Kamis","Jumat","Sabtu","Minggu")) -> Rabu | ... AQ3: =IF(AQ2="","",CHOOSE(WEEKDAY(AQ2,2),"Senin","Selasa","Rabu","Kamis","Jumat","Sabtu","Minggu"))
B4: 1 | C4: =DATA_GURU!C3&" ["&DATA_GURU!D3&"]" -> Dewi Andriani, S.Pd [Matematika] | F4: Libur Tanggal Merah | G4: Libur | H4: MINGGU | J4: Mengajar | M4: Mengajar | O4: MINGGU | Q4: Mengajar | T4: Mengajar | V4: MINGGU | X4: Mengajar | AA4: Mengajar | AC4: MINGGU | AE4: Mengajar | AH4: Mengajar
B5: 2 | C5: =DATA_GURU!C4&" ["&DATA_GURU!D4&"]" -> Wiwin Nitasari, S.Pd [PKN] | D5: Libur Tanggal Merah | F5: Libur Tanggal Merah | G5: Libur | H5: MINGGU | I5: Mengajar | J5: Mengajar | K5: Mengajar | M5: Mengajar | O5: MINGGU | P5: Mengajar | Q5: Mengajar | R5: Mengajar | T5: Mengajar | V5: MINGGU | W5: Mengajar | X5: Mengajar | Y5: Mengajar | AA5: Mengajar | AC5: MINGGU | AD5: Mengajar | AE5: Mengajar | AF5: Mengajar | AH5: Mengajar
B6: 3 | C6: =DATA_GURU!C5&" ["&DATA_GURU!D5&"]" -> Indra Kurniawan, A.Md [Prakarya - TIK] | E6: Libur Tanggal Merah | G6: Libur | H6: MINGGU | I6: Mengajar | J6: Mengajar | L6: Mengajar | N6: Libur | O6: MINGGU | P6: Mengajar | Q6: Mengajar | S6: Mengajar | U6: Libur | V6: MINGGU | W6: Mengajar | X6: Mengajar | Z6: Mengajar | AB6: Libur | AC6: MINGGU | AD6: Mengajar | AE6: Mengajar | AG6: Mengajar
B7: 4 | C7: =DATA_GURU!C6&" ["&DATA_GURU!D6&"]" -> Siti Satriah, S.Pd [B. Inggris] | F7: Libur Tanggal Merah | G7: Libur | H7: MINGGU | I7: Mengajar | J7: Mengajar | M7: Mengajar | N7: Libur | O7: MINGGU | P7: Mengajar | Q7: Mengajar | T7: Mengajar | U7: Libur | V7: MINGGU | W7: Mengajar | X7: Mengajar | AA7: Mengajar | AB7: Libur | AC7: MINGGU | AD7: Mengajar | AE7: Mengajar | AH7: Mengajar
B8: 5 | C8: =DATA_GURU!C7&" ["&DATA_GURU!D7&"]" -> Klidia Nurwulan, S.Pd [B. Indonesia] | E8: Libur Tanggal Merah | F8: Libur Tanggal Merah | G8: Libur | H8: MINGGU | I8: Mengajar | J8: Mengajar | L8: Mengajar | M8: Mengajar | N8: Libur | O8: MINGGU | P8: Mengajar | Q8: Mengajar | S8: Mengajar | T8: Mengajar | U8: Libur | V8: MINGGU | W8: Mengajar | X8: Mengajar | Z8: Mengajar | AA8: Mengajar | AB8: Libur | AC8: MINGGU | AD8: Mengajar | AE8: Mengajar | AG8: Mengajar | AH8: Mengajar
B9: 6 | C9: =DATA_GURU!C8&" ["&DATA_GURU!D8&"]" -> Putri Megawati, S.Pd [PJOK] | D9: Libur Tanggal Merah | F9: Libur Tanggal Merah | G9: Libur | H9: MINGGU | J9: Mengajar | K9: Mengajar | M9: Mengajar | N9: Libur | O9: MINGGU | Q9: Mengajar | R9: Mengajar | T9: Mengajar | U9: Libur | V9: MINGGU | X9: Mengajar | Y9: Mengajar | AA9: Mengajar | AB9: Libur | AC9: MINGGU | AE9: Mengajar | AF9: Mengajar | AH9: Mengajar
B10: 7 | C10: =DATA_GURU!C9&" ["&DATA_GURU!D9&"]" -> Dani Ramdhani, S.Pd [B. Inggris] | D10: Libur Tanggal Merah | F10: Libur Tanggal Merah | G10: Libur | H10: MINGGU | J10: Mengajar | K10: Mengajar | M10: Mengajar | N10: Libur | O10: MINGGU | Q10: Mengajar | R10: Mengajar | T10: Mengajar | U10: Libur | V10: MINGGU | X10: Mengajar | Y10: Mengajar | AA10: Mengajar | AB10: Libur | AC10: MINGGU | AE10: Mengajar | AF10: Mengajar | AH10: Mengajar
B11: 8 | C11: =DATA_GURU!C10&" ["&DATA_GURU!D10&"]" -> Shafa Padilah S. S.Pd [B. Indonesia] | D11: Libur Tanggal Merah | F11: Libur Tanggal Merah | G11: Libur | H11: MINGGU | I11: Mengajar | J11: Mengajar | K11: Mengajar | M11: Mengajar | N11: Libur | O11: MINGGU | P11: Mengajar | Q11: Mengajar | R11: Mengajar | T11: Mengajar | U11: Libur | V11: MINGGU | W11: Mengajar | X11: Mengajar | Y11: Mengajar | AA11: Mengajar | AB11: Libur | AC11: MINGGU | AD11: Mengajar | AE11: Mengajar | AF11: Mengajar | AH11: Mengajar
B12: 9 | C12: =DATA_GURU!C11&" ["&DATA_GURU!D11&"]" -> Imam Hasbulloh, S.Pd [Matematika] | D12: Libur Tanggal Merah | E12: Libur Tanggal Merah | F12: Libur Tanggal Merah | G12: Libur | H12: MINGGU | I12: Mengajar | J12: Mengajar | K12: Mengajar | L12: Mengajar | M12: Mengajar | N12: Libur | O12: MINGGU | P12: Mengajar | Q12: Mengajar | R12: Mengajar | S12: Mengajar | T12: Mengajar | U12: Libur | V12: MINGGU | W12: Mengajar | X12: Mengajar | Y12: Mengajar | Z12: Mengajar | AA12: Mengajar | AB12: Libur | AC12: MINGGU | AD12: Mengajar | AE12: Mengajar | AF12: Mengajar | AG12: Mengajar | AH12: Mengajar
B13: 10 | C13: =DATA_GURU!C12&" ["&DATA_GURU!D12&"]" -> Muhamad Aldiansyah [B. Inggris] | D13: Libur Tanggal Merah | E13: Libur Tanggal Merah | G13: Libur | H13: MINGGU | I13: Mengajar | J13: Mengajar | K13: Mengajar | L13: Mengajar | N13: Libur | O13: MINGGU | P13: Mengajar | Q13: Mengajar | R13: Mengajar | S13: Mengajar | U13: Libur | V13: MINGGU | W13: Mengajar | X13: Mengajar | Y13: Mengajar | Z13: Mengajar | AB13: Libur | AC13: MINGGU | AD13: Mengajar | AE13: Mengajar | AF13: Mengajar | AG13: Mengajar
B14: 11 | C14: =DATA_GURU!C13&" ["&DATA_GURU!D13&"]" -> M. Fadilah Abdurahman [Seni Budaya] | D14: Libur Tanggal Merah | E14: Libur Tanggal Merah | F14: Libur Tanggal Merah | G14: Libur | H14: MINGGU | J14: Mengajar | K14: Mengajar | L14: Mengajar | M14: Mengajar | N14: Libur | O14: MINGGU | Q14: Mengajar | R14: Mengajar | S14: Mengajar | T14: Mengajar | U14: Libur | V14: MINGGU | X14: Mengajar | Y14: Mengajar | Z14: Mengajar | AA14: Mengajar | AB14: Libur | AC14: MINGGU | AE14: Mengajar | AF14: Mengajar | AG14: Mengajar | AH14: Mengajar
B15: 12 | C15: =DATA_GURU!C14&" ["&DATA_GURU!D14&"]" -> Ahmad Yusup [TIK] | D15: Libur Tanggal Merah | E15: Libur Tanggal Merah | F15: Libur Tanggal Merah | G15: Libur | H15: MINGGU | I15: Mengajar | K15: Mengajar | L15: Mengajar | M15: Mengajar | N15: Libur | O15: MINGGU | P15: Mengajar | R15: Mengajar | S15: Mengajar | T15: Mengajar | U15: Libur | V15: MINGGU | W15: Mengajar | Y15: Mengajar | Z15: Mengajar | AA15: Mengajar | AB15: Libur | AC15: MINGGU | AD15: Mengajar | AF15: Mengajar | AG15: Mengajar | AH15: Mengajar
B16: 13 | C16: =DATA_GURU!C15&" ["&DATA_GURU!D15&"]" -> Ai Rabiah Nur Syabani, S.Hum., S.Pd [PAI] | D16: Libur Tanggal Merah | E16: Libur Tanggal Merah | F16: Libur Tanggal Merah | G16: Libur | H16: MINGGU | J16: Mengajar | K16: Mengajar | L16: Mengajar | M16: Mengajar | N16: Libur | O16: MINGGU | Q16: Mengajar | R16: Mengajar | S16: Mengajar | T16: Mengajar | U16: Libur | V16: MINGGU | X16: Mengajar | Y16: Mengajar | Z16: Mengajar | AA16: Mengajar | AB16: Libur | AC16: MINGGU | AE16: Mengajar | AF16: Mengajar | AG16: Mengajar | AH16: Mengajar
B17: 14 | C17: =DATA_GURU!C16&" ["&DATA_GURU!D16&"]" -> Deni Sastra Dinata, S.H [IPS] | D17: Libur Tanggal Merah | E17: Libur Tanggal Merah | F17: Libur Tanggal Merah | G17: Libur | H17: MINGGU | I17: Mengajar | J17: Mengajar | K17: Mengajar | L17: Mengajar | M17: Mengajar | N17: Libur | O17: MINGGU | P17: Mengajar | Q17: Mengajar | R17: Mengajar | S17: Mengajar | T17: Mengajar | U17: Libur | V17: MINGGU | W17: Mengajar | X17: Mengajar | Y17: Mengajar | Z17: Mengajar | AA17: Mengajar | AB17: Libur | AC17: MINGGU | AD17: Mengajar | AE17: Mengajar | AF17: Mengajar | AG17: Mengajar | AH17: Mengajar
B18: 15 | C18: =DATA_GURU!C17&" ["&DATA_GURU!D17&"]" -> Tasya Salsabila, S.Pd [IPA - MTK] | E18: Libur Tanggal Merah | F18: Libur Tanggal Merah | G18: Libur | H18: MINGGU | I18: Mengajar | J18: Mengajar | L18: Mengajar | M18: Mengajar | N18: Libur | O18: MINGGU | P18: Mengajar | Q18: Mengajar | S18: Mengajar | T18: Mengajar | U18: Libur | V18: MINGGU | W18: Mengajar | X18: Mengajar | Z18: Mengajar | AA18: Mengajar | AB18: Libur | AC18: MINGGU | AD18: Mengajar | AE18: Mengajar | AG18: Mengajar | AH18: Mengajar
B19: 16 | C19: =DATA_GURU!C18&" ["&DATA_GURU!D18&"]" -> Nana Fauziah, S.Pd [PAI] | D19: Libur Tanggal Merah | F19: Libur Tanggal Merah | G19: Libur | H19: MINGGU | I19: Mengajar | K19: Mengajar | M19: Mengajar | N19: Libur | O19: MINGGU | P19: Mengajar | R19: Mengajar | T19: Mengajar | U19: Libur | V19: MINGGU | W19: Mengajar | Y19: Mengajar | AA19: Mengajar | AB19: Libur | AC19: MINGGU | AD19: Mengajar | AF19: Mengajar | AH19: Mengajar
B20: 17 | C20: =DATA_GURU!C19&" ["&DATA_GURU!D19&"]" -> Ajeng Putri Rahayu, S.Pd [B. Sunda] | D20: Libur Tanggal Merah | E20: Libur Tanggal Merah | F20: Libur Tanggal Merah | G20: Libur | H20: MINGGU | I20: Mengajar | K20: Mengajar | L20: Mengajar | M20: Mengajar | N20: Libur | O20: MINGGU | P20: Mengajar | R20: Mengajar | S20: Mengajar | T20: Mengajar | U20: Libur | V20: MINGGU | W20: Mengajar | Y20: Mengajar | Z20: Mengajar | AA20: Mengajar | AB20: Libur | AC20: MINGGU | AD20: Mengajar | AF20: Mengajar | AG20: Mengajar | AH20: Mengajar
B21: 18 | C21: =DATA_GURU!C20&" ["&DATA_GURU!D20&"]" -> Febri Nugraha, S.Hum [IPS] | D21: Libur Tanggal Merah | E21: Libur Tanggal Merah | F21: Libur Tanggal Merah | G21: Libur | H21: MINGGU | I21: Mengajar | K21: Mengajar | L21: Mengajar | M21: Mengajar | N21: Libur | O21: MINGGU | P21: Mengajar | R21: Mengajar | S21: Mengajar | T21: Mengajar | U21: Libur | V21: MINGGU | W21: Mengajar | Y21: Mengajar | Z21: Mengajar | AA21: Mengajar | AB21: Libur | AC21: MINGGU | AD21: Mengajar | AF21: Mengajar | AG21: Mengajar | AH21: Mengajar
B22: 19 | C22: =DATA_GURU!C21&" ["&DATA_GURU!D21&"]" -> Dadang Try Subekti, S.Pd [IPA] | D22: Libur Tanggal Merah | E22: Libur Tanggal Merah | F22: Libur Tanggal Merah | G22: Libur | H22: MINGGU | J22: Mengajar | K22: Mengajar | L22: Mengajar | M22: Mengajar | N22: Libur | O22: MINGGU | Q22: Mengajar | R22: Mengajar | S22: Mengajar | T22: Mengajar | U22: Libur | V22: MINGGU | X22: Mengajar | Y22: Mengajar | Z22: Mengajar | AA22: Mengajar | AB22: Libur | AC22: MINGGU | AE22: Mengajar | AF22: Mengajar | AG22: Mengajar | AH22: Mengajar
B23: 20 | C23: =DATA_GURU!C22&" ["&DATA_GURU!D22&"]" -> Abdullah Nurrachman Soleh, S.Pd [PJOK] | E23: Libur Tanggal Merah | F23: Libur Tanggal Merah | G23: Libur | H23: MINGGU | I23: Mengajar | J23: Mengajar | L23: Mengajar | M23: Mengajar | N23: Libur | O23: MINGGU | P23: Mengajar | Q23: Mengajar | S23: Mengajar | T23: Mengajar | U23: Libur | V23: MINGGU | W23: Mengajar | X23: Mengajar | Z23: Mengajar | AA23: Mengajar | AB23: Libur | AC23: MINGGU | AD23: Mengajar | AE23: Mengajar | AG23: Mengajar | AH23: Mengajar

Sheet REKAP_BULANAN
B1: REKAP ABSENSI MENGAJAR GURU UMUM · SMP Plus YPP Darussurur
B2: ="PERIODE "&TEXT(CONFIG!C4,"DD MMMM YYYY")&" s.d. "&TEXT(CONFIG!C5,"DD MMMM YYYY") -> PERIODE 25 March 2026 s.d. 24 April 2026
B4: No | C4: Nama Guru | D4: Mata Pelajaran | E4: STATUS KEHADIRAN BERDASARKAN JAM PELAJARAN | K4: STATUS KEHADIRAN BERDASARKAN HARI AKTIF MENGAJAR | O4: % KEHADIRAN (Jam) | P4: Hari Berjadwal
E5: Target Jam | F5: Jam Hadir | G5: Jam Sakit | H5: Jam Izin | I5: Jam Tanpa Keterangan | J5: Total Tidak Hadir | K5: Hari Hadir | L5: Hari Sakit | M5: Hari Izin | N5: Hari Tanpa Keterangan
B7: 1 | C7: Dewi Andriani, S.Pd | D7: Matematika | E7: =SUMPRODUCT((ABSENSI!D$3:AQ$3="Senin")*IFERROR(VLOOKUP($C7,DATA_JAM_PELAJARAN!$C:$K,3,0),0)+(ABSENSI!D$3:AQ$3="Selasa")*IFERROR(VLOOKUP($C7,DATA_JAM_PELAJARAN!$C:$K,4,0),0)+(ABSENSI!D$3:AQ$3="Rabu")*IFERROR(VLOOKUP($C7,DATA_JAM_PELAJARAN!$C:$K,5,0),0)+(ABSENSI!D$3:AQ$3="Kamis")*IFERROR(VLOOKUP($C7,DATA_JAM_PELAJARAN!$C:$K,6,0),0)+(ABSENSI!D$3:AQ$3="Jumat")*IFERROR(VLOOKUP($C7,DATA_JAM_PELAJARAN!$C:$K,7,0),0)+(ABSENSI!D$3:AQ$3="Sabtu")*IFERROR(VLOOKUP($C7,DATA_JAM_PELAJARAN!$C:$K,8,0),0)) -> 46 | F7: =SUMPRODUCT((ABSENSI!D4:AQ4="Mengajar")*((ABSENSI!D$3:AQ$3="Senin")*IFERROR(VLOOKUP($C7,DATA_JAM_PELAJARAN!$C:$K,3,0),0)+(ABSENSI!D$3:AQ$3="Selasa")*IFERROR(VLOOKUP($C7,DATA_JAM_PELAJARAN!$C:$K,4,0),0)+(ABSENSI!D$3:AQ$3="Rabu")*IFERROR(VLOOKUP($C7,DATA_JAM_PELAJARAN!$C:$K,5,0),0)+(ABSENSI!D$3:AQ$3="Kamis")*IFERROR(VLOOKUP($C7,DATA_JAM_PELAJARAN!$C:$K,6,0),0)+(ABSENSI!D$3:AQ$3="Jumat")*IFERROR(VLOOKUP($C7,DATA_JAM_PELAJARAN!$C:$K,7,0),0)+(ABSENSI!D$3:AQ$3="Sabtu")*IFERROR(VLOOKUP($C7,DATA_JAM_PELAJARAN!$C:$K,8,0),0))) -> 40 | G7: =SUMPRODUCT((ABSENSI!D4:AQ4="Sakit")*((ABSENSI!D$3:AQ$3="Senin")*IFERROR(VLOOKUP($C7,DATA_JAM_PELAJARAN!$C:$K,3,0),0)+(ABSENSI!D$3:AQ$3="Selasa")*IFERROR(VLOOKUP($C7,DATA_JAM_PELAJARAN!$C:$K,4,0),0)+(ABSENSI!D$3:AQ$3="Rabu")*IFERROR(VLOOKUP($C7,DATA_JAM_PELAJARAN!$C:$K,5,0),0)+(ABSENSI!D$3:AQ$3="Kamis")*IFERROR(VLOOKUP($C7,DATA_JAM_PELAJARAN!$C:$K,6,0),0)+(ABSENSI!D$3:AQ$3="Jumat")*IFERROR(VLOOKUP($C7,DATA_JAM_PELAJARAN!$C:$K,7,0),0)+(ABSENSI!D$3:AQ$3="Sabtu")*IFERROR(VLOOKUP($C7,DATA_JAM_PELAJARAN!$C:$K,8,0),0))) -> 0 | H7: =SUMPRODUCT((ABSENSI!D4:AQ4="Izin")*((ABSENSI!D$3:AQ$3="Senin")*IFERROR(VLOOKUP($C7,DATA_JAM_PELAJARAN!$C:$K,3,0),0)+(ABSENSI!D$3:AQ$3="Selasa")*IFERROR(VLOOKUP($C7,DATA_JAM_PELAJARAN!$C:$K,4,0),0)+(ABSENSI!D$3:AQ$3="Rabu")*IFERROR(VLOOKUP($C7,DATA_JAM_PELAJARAN!$C:$K,5,0),0)+(ABSENSI!D$3:AQ$3="Kamis")*IFERROR(VLOOKUP($C7,DATA_JAM_PELAJARAN!$C:$K,6,0),0)+(ABSENSI!D$3:AQ$3="Jumat")*IFERROR(VLOOKUP($C7,DATA_JAM_PELAJARAN!$C:$K,7,0),0)+(ABSENSI!D$3:AQ$3="Sabtu")*IFERROR(VLOOKUP($C7,DATA_JAM_PELAJARAN!$C:$K,8,0),0))) -> 0 | I7: =SUMPRODUCT((ABSENSI!D4:AQ4="Tanpa Keterangan")*((ABSENSI!D$3:AQ$3="Senin")*IFERROR(VLOOKUP($C7,DATA_JAM_PELAJARAN!$C:$K,3,0),0)+(ABSENSI!D$3:AQ$3="Selasa")*IFERROR(VLOOKUP($C7,DATA_JAM_PELAJARAN!$C:$K,4,0),0)+(ABSENSI!D$3:AQ$3="Rabu")*IFERROR(VLOOKUP($C7,DATA_JAM_PELAJARAN!$C:$K,5,0),0)+(ABSENSI!D$3:AQ$3="Kamis")*IFERROR(VLOOKUP($C7,DATA_JAM_PELAJARAN!$C:$K,6,0),0)+(ABSENSI!D$3:AQ$3="Jumat")*IFERROR(VLOOKUP($C7,DATA_JAM_PELAJARAN!$C:$K,7,0),0)+(ABSENSI!D$3:AQ$3="Sabtu")*IFERROR(VLOOKUP($C7,DATA_JAM_PELAJARAN!$C:$K,8,0),0))) -> 0 | J7: =SUM(G7:I7) -> 0 | K7: =COUNTIF(ABSENSI!D4:AQ4,"Mengajar") -> 8 | L7: =COUNTIF(ABSENSI!D4:AQ4,"Sakit") -> 0 | M7: =COUNTIF(ABSENSI!D4:AQ4,"Izin") -> 0 | N7: =COUNTIF(ABSENSI!D4:AQ4,"Tanpa Keterangan") -> 0 | O7: =IFERROR(F7/E7,0) -> 0.86956522 | P7: =SUMPRODUCT((ABSENSI!D$3:AQ$3="Senin")*(IFERROR(VLOOKUP($C7,DATA_JAM_PELAJARAN!$C:$K,3,0),0)>0)+(ABSENSI!D$3:AQ$3="Selasa")*(IFERROR(VLOOKUP($C7,DATA_JAM_PELAJARAN!$C:$K,4,0),0)>0)+(ABSENSI!D$3:AQ$3="Rabu")*(IFERROR(VLOOKUP($C7,DATA_JAM_PELAJARAN!$C:$K,5,0),0)>0)+(ABSENSI!D$3:AQ$3="Kamis")*(IFERROR(VLOOKUP($C7,DATA_JAM_PELAJARAN!$C:$K,6,0),0)>0)+(ABSENSI!D$3:AQ$3="Jumat")*(IFERROR(VLOOKUP($C7,DATA_JAM_PELAJARAN!$C:$K,7,0),0)>0)+(ABSENSI!D$3:AQ$3="Sabtu")*(IFERROR(VLOOKUP($C7,DATA_JAM_PELAJARAN!$C:$K,8,0),0)>0)) -> 9
B8: 2 | C8: Wiwin Nitasari, S.Pd | D8: PKN | E8: =SUMPRODUCT((ABSENSI!D$3:AQ$3="Senin")*IFERROR(VLOOKUP($C8,DATA_JAM_PELAJARAN!$C:$K,3,0),0)+(ABSENSI!D$3:AQ$3="Selasa")*IFERROR(VLOOKUP($C8,DATA_JAM_PELAJARAN!$C:$K,4,0),0)+(ABSENSI!D$3:AQ$3="Rabu")*IFERROR(VLOOKUP($C8,DATA_JAM_PELAJARAN!$C:$K,5,0),0)+(ABSENSI!D$3:AQ$3="Kamis")*IFERROR(VLOOKUP($C8,DATA_JAM_PELAJARAN!$C:$K,6,0),0)+(ABSENSI!D$3:AQ$3="Jumat")*IFERROR(VLOOKUP($C8,DATA_JAM_PELAJARAN!$C:$K,7,0),0)+(ABSENSI!D$3:AQ$3="Sabtu")*IFERROR(VLOOKUP($C8,DATA_JAM_PELAJARAN!$C:$K,8,0),0)) -> 147 | F8: =SUMPRODUCT((ABSENSI!D5:AQ5="Mengajar")*((ABSENSI!D$3:AQ$3="Senin")*IFERROR(VLOOKUP($C8,DATA_JAM_PELAJARAN!$C:$K,3,0),0)+(ABSENSI!D$3:AQ$3="Selasa")*IFERROR(VLOOKUP($C8,DATA_JAM_PELAJARAN!$C:$K,4,0),0)+(ABSENSI!D$3:AQ$3="Rabu")*IFERROR(VLOOKUP($C8,DATA_JAM_PELAJARAN!$C:$K,5,0),0)+(ABSENSI!D$3:AQ$3="Kamis")*IFERROR(VLOOKUP($C8,DATA_JAM_PELAJARAN!$C:$K,6,0),0)+(ABSENSI!D$3:AQ$3="Jumat")*IFERROR(VLOOKUP($C8,DATA_JAM_PELAJARAN!$C:$K,7,0),0)+(ABSENSI!D$3:AQ$3="Sabtu")*IFERROR(VLOOKUP($C8,DATA_JAM_PELAJARAN!$C:$K,8,0),0))) -> 132 | G8: =SUMPRODUCT((ABSENSI!D5:AQ5="Sakit")*((ABSENSI!D$3:AQ$3="Senin")*IFERROR(VLOOKUP($C8,DATA_JAM_PELAJARAN!$C:$K,3,0),0)+(ABSENSI!D$3:AQ$3="Selasa")*IFERROR(VLOOKUP($C8,DATA_JAM_PELAJARAN!$C:$K,4,0),0)+(ABSENSI!D$3:AQ$3="Rabu")*IFERROR(VLOOKUP($C8,DATA_JAM_PELAJARAN!$C:$K,5,0),0)+(ABSENSI!D$3:AQ$3="Kamis")*IFERROR(VLOOKUP($C8,DATA_JAM_PELAJARAN!$C:$K,6,0),0)+(ABSENSI!D$3:AQ$3="Jumat")*IFERROR(VLOOKUP($C8,DATA_JAM_PELAJARAN!$C:$K,7,0),0)+(ABSENSI!D$3:AQ$3="Sabtu")*IFERROR(VLOOKUP($C8,DATA_JAM_PELAJARAN!$C:$K,8,0),0))) -> 0 | H8: =SUMPRODUCT((ABSENSI!D5:AQ5="Izin")*((ABSENSI!D$3:AQ$3="Senin")*IFERROR(VLOOKUP($C8,DATA_JAM_PELAJARAN!$C:$K,3,0),0)+(ABSENSI!D$3:AQ$3="Selasa")*IFERROR(VLOOKUP($C8,DATA_JAM_PELAJARAN!$C:$K,4,0),0)+(ABSENSI!D$3:AQ$3="Rabu")*IFERROR(VLOOKUP($C8,DATA_JAM_PELAJARAN!$C:$K,5,0),0)+(ABSENSI!D$3:AQ$3="Kamis")*IFERROR(VLOOKUP($C8,DATA_JAM_PELAJARAN!$C:$K,6,0),0)+(ABSENSI!D$3:AQ$3="Jumat")*IFERROR(VLOOKUP($C8,DATA_JAM_PELAJARAN!$C:$K,7,0),0)+(ABSENSI!D$3:AQ$3="Sabtu")*IFERROR(VLOOKUP($C8,DATA_JAM_PELAJARAN!$C:$K,8,0),0))) -> 0 | I8: =SUMPRODUCT((ABSENSI!D5:AQ5="Tanpa Keterangan")*((ABSENSI!D$3:AQ$3="Senin")*IFERROR(VLOOKUP($C8,DATA_JAM_PELAJARAN!$C:$K,3,0),0)+(ABSENSI!D$3:AQ$3="Selasa")*IFERROR(VLOOKUP($C8,DATA_JAM_PELAJARAN!$C:$K,4,0),0)+(ABSENSI!D$3:AQ$3="Rabu")*IFERROR(VLOOKUP($C8,DATA_JAM_PELAJARAN!$C:$K,5,0),0)+(ABSENSI!D$3:AQ$3="Kamis")*IFERROR(VLOOKUP($C8,DATA_JAM_PELAJARAN!$C:$K,6,0),0)+(ABSENSI!D$3:AQ$3="Jumat")*IFERROR(VLOOKUP($C8,DATA_JAM_PELAJARAN!$C:$K,7,0),0)+(ABSENSI!D$3:AQ$3="Sabtu")*IFERROR(VLOOKUP($C8,DATA_JAM_PELAJARAN!$C:$K,8,0),0))) -> 0 | J8: =SUM(G8:I8) -> 0 | K8: =COUNTIF(ABSENSI!D5:AQ5,"Mengajar") -> 16 | L8: =COUNTIF(ABSENSI!D5:AQ5,"Sakit") -> 0 | M8: =COUNTIF(ABSENSI!D5:AQ5,"Izin") -> 0 | N8: =COUNTIF(ABSENSI!D5:AQ5,"Tanpa Keterangan") -> 0 | O8: =IFERROR(F8/E8,0) -> 0.89795918 | P8: =SUMPRODUCT((ABSENSI!D$3:AQ$3="Senin")*(IFERROR(VLOOKUP($C8,DATA_JAM_PELAJARAN!$C:$K,3,0),0)>0)+(ABSENSI!D$3:AQ$3="Selasa")*(IFERROR(VLOOKUP($C8,DATA_JAM_PELAJARAN!$C:$K,4,0),0)>0)+(ABSENSI!D$3:AQ$3="Rabu")*(IFERROR(VLOOKUP($C8,DATA_JAM_PELAJARAN!$C:$K,5,0),0)>0)+(ABSENSI!D$3:AQ$3="Kamis")*(IFERROR(VLOOKUP($C8,DATA_JAM_PELAJARAN!$C:$K,6,0),0)>0)+(ABSENSI!D$3:AQ$3="Jumat")*(IFERROR(VLOOKUP($C8,DATA_JAM_PELAJARAN!$C:$K,7,0),0)>0)+(ABSENSI!D$3:AQ$3="Sabtu")*(IFERROR(VLOOKUP($C8,DATA_JAM_PELAJARAN!$C:$K,8,0),0)>0)) -> 18
B9: 3 | C9: Indra Kurniawan, A.Md | D9: Prakarya - TIK | E9: =SUMPRODUCT((ABSENSI!D$3:AQ$3="Senin")*IFERROR(VLOOKUP($C9,DATA_JAM_PELAJARAN!$C:$K,3,0),0)+(ABSENSI!D$3:AQ$3="Selasa")*IFERROR(VLOOKUP($C9,DATA_JAM_PELAJARAN!$C:$K,4,0),0)+(ABSENSI!D$3:AQ$3="Rabu")*IFERROR(VLOOKUP($C9,DATA_JAM_PELAJARAN!$C:$K,5,0),0)+(ABSENSI!D$3:AQ$3="Kamis")*IFERROR(VLOOKUP($C9,DATA_JAM_PELAJARAN!$C:$K,6,0),0)+(ABSENSI!D$3:AQ$3="Jumat")*IFERROR(VLOOKUP($C9,DATA_JAM_PELAJARAN!$C:$K,7,0),0)+(ABSENSI!D$3:AQ$3="Sabtu")*IFERROR(VLOOKUP($C9,DATA_JAM_PELAJARAN!$C:$K,8,0),0)) -> 60 | F9: =SUMPRODUCT((ABSENSI!D6:AQ6="Mengajar")*((ABSENSI!D$3:AQ$3="Senin")*IFERROR(VLOOKUP($C9,DATA_JAM_PELAJARAN!$C:$K,3,0),0)+(ABSENSI!D$3:AQ$3="Selasa")*IFERROR(VLOOKUP($C9,DATA_JAM_PELAJARAN!$C:$K,4,0),0)+(ABSENSI!D$3:AQ$3="Rabu")*IFERROR(VLOOKUP($C9,DATA_JAM_PELAJARAN!$C:$K,5,0),0)+(ABSENSI!D$3:AQ$3="Kamis")*IFERROR(VLOOKUP($C9,DATA_JAM_PELAJARAN!$C:$K,6,0),0)+(ABSENSI!D$3:AQ$3="Jumat")*IFERROR(VLOOKUP($C9,DATA_JAM_PELAJARAN!$C:$K,7,0),0)+(ABSENSI!D$3:AQ$3="Sabtu")*IFERROR(VLOOKUP($C9,DATA_JAM_PELAJARAN!$C:$K,8,0),0))) -> 56 | G9: =SUMPRODUCT((ABSENSI!D6:AQ6="Sakit")*((ABSENSI!D$3:AQ$3="Senin")*IFERROR(VLOOKUP($C9,DATA_JAM_PELAJARAN!$C:$K,3,0),0)+(ABSENSI!D$3:AQ$3="Selasa")*IFERROR(VLOOKUP($C9,DATA_JAM_PELAJARAN!$C:$K,4,0),0)+(ABSENSI!D$3:AQ$3="Rabu")*IFERROR(VLOOKUP($C9,DATA_JAM_PELAJARAN!$C:$K,5,0),0)+(ABSENSI!D$3:AQ$3="Kamis")*IFERROR(VLOOKUP($C9,DATA_JAM_PELAJARAN!$C:$K,6,0),0)+(ABSENSI!D$3:AQ$3="Jumat")*IFERROR(VLOOKUP($C9,DATA_JAM_PELAJARAN!$C:$K,7,0),0)+(ABSENSI!D$3:AQ$3="Sabtu")*IFERROR(VLOOKUP($C9,DATA_JAM_PELAJARAN!$C:$K,8,0),0))) -> 0 | H9: =SUMPRODUCT((ABSENSI!D6:AQ6="Izin")*((ABSENSI!D$3:AQ$3="Senin")*IFERROR(VLOOKUP($C9,DATA_JAM_PELAJARAN!$C:$K,3,0),0)+(ABSENSI!D$3:AQ$3="Selasa")*IFERROR(VLOOKUP($C9,DATA_JAM_PELAJARAN!$C:$K,4,0),0)+(ABSENSI!D$3:AQ$3="Rabu")*IFERROR(VLOOKUP($C9,DATA_JAM_PELAJARAN!$C:$K,5,0),0)+(ABSENSI!D$3:AQ$3="Kamis")*IFERROR(VLOOKUP($C9,DATA_JAM_PELAJARAN!$C:$K,6,0),0)+(ABSENSI!D$3:AQ$3="Jumat")*IFERROR(VLOOKUP($C9,DATA_JAM_PELAJARAN!$C:$K,7,0),0)+(ABSENSI!D$3:AQ$3="Sabtu")*IFERROR(VLOOKUP($C9,DATA_JAM_PELAJARAN!$C:$K,8,0),0))) -> 0 | I9: =SUMPRODUCT((ABSENSI!D6:AQ6="Tanpa Keterangan")*((ABSENSI!D$3:AQ$3="Senin")*IFERROR(VLOOKUP($C9,DATA_JAM_PELAJARAN!$C:$K,3,0),0)+(ABSENSI!D$3:AQ$3="Selasa")*IFERROR(VLOOKUP($C9,DATA_JAM_PELAJARAN!$C:$K,4,0),0)+(ABSENSI!D$3:AQ$3="Rabu")*IFERROR(VLOOKUP($C9,DATA_JAM_PELAJARAN!$C:$K,5,0),0)+(ABSENSI!D$3:AQ$3="Kamis")*IFERROR(VLOOKUP($C9,DATA_JAM_PELAJARAN!$C:$K,6,0),0)+(ABSENSI!D$3:AQ$3="Jumat")*IFERROR(VLOOKUP($C9,DATA_JAM_PELAJARAN!$C:$K,7,0),0)+(ABSENSI!D$3:AQ$3="Sabtu")*IFERROR(VLOOKUP($C9,DATA_JAM_PELAJARAN!$C:$K,8,0),0))) -> 0 | J9: =SUM(G9:I9) -> 0 | K9: =COUNTIF(ABSENSI!D6:AQ6,"Mengajar") -> 12 | L9: =COUNTIF(ABSENSI!D6:AQ6,"Sakit") -> 0 | M9: =COUNTIF(ABSENSI!D6:AQ6,"Izin") -> 0 | N9: =COUNTIF(ABSENSI!D6:AQ6,"Tanpa Keterangan") -> 0 | O9: =IFERROR(F9/E9,0) -> 0.93333333 | P9: =SUMPRODUCT((ABSENSI!D$3:AQ$3="Senin")*(IFERROR(VLOOKUP($C9,DATA_JAM_PELAJARAN!$C:$K,3,0),0)>0)+(ABSENSI!D$3:AQ$3="Selasa")*(IFERROR(VLOOKUP($C9,DATA_JAM_PELAJARAN!$C:$K,4,0),0)>0)+(ABSENSI!D$3:AQ$3="Rabu")*(IFERROR(VLOOKUP($C9,DATA_JAM_PELAJARAN!$C:$K,5,0),0)>0)+(ABSENSI!D$3:AQ$3="Kamis")*(IFERROR(VLOOKUP($C9,DATA_JAM_PELAJARAN!$C:$K,6,0),0)>0)+(ABSENSI!D$3:AQ$3="Jumat")*(IFERROR(VLOOKUP($C9,DATA_JAM_PELAJARAN!$C:$K,7,0),0)>0)+(ABSENSI!D$3:AQ$3="Sabtu")*(IFERROR(VLOOKUP($C9,DATA_JAM_PELAJARAN!$C:$K,8,0),0)>0)) -> 13
B10: 4 | C10: Siti Satriah, S.Pd | D10: B. Inggris | E10: =SUMPRODUCT((ABSENSI!D$3:AQ$3="Senin")*IFERROR(VLOOKUP($C10,DATA_JAM_PELAJARAN!$C:$K,3,0),0)+(ABSENSI!D$3:AQ$3="Selasa")*IFERROR(VLOOKUP($C10,DATA_JAM_PELAJARAN!$C:$K,4,0),0)+(ABSENSI!D$3:AQ$3="Rabu")*IFERROR(VLOOKUP($C10,DATA_JAM_PELAJARAN!$C:$K,5,0),0)+(ABSENSI!D$3:AQ$3="Kamis")*IFERROR(VLOOKUP($C10,DATA_JAM_PELAJARAN!$C:$K,6,0),0)+(ABSENSI!D$3:AQ$3="Jumat")*IFERROR(VLOOKUP($C10,DATA_JAM_PELAJARAN!$C:$K,7,0),0)+(ABSENSI!D$3:AQ$3="Sabtu")*IFERROR(VLOOKUP($C10,DATA_JAM_PELAJARAN!$C:$K,8,0),0)) -> 72 | F10: =SUMPRODUCT((ABSENSI!D7:AQ7="Mengajar")*((ABSENSI!D$3:AQ$3="Senin")*IFERROR(VLOOKUP($C10,DATA_JAM_PELAJARAN!$C:$K,3,0),0)+(ABSENSI!D$3:AQ$3="Selasa")*IFERROR(VLOOKUP($C10,DATA_JAM_PELAJARAN!$C:$K,4,0),0)+(ABSENSI!D$3:AQ$3="Rabu")*IFERROR(VLOOKUP($C10,DATA_JAM_PELAJARAN!$C:$K,5,0),0)+(ABSENSI!D$3:AQ$3="Kamis")*IFERROR(VLOOKUP($C10,DATA_JAM_PELAJARAN!$C:$K,6,0),0)+(ABSENSI!D$3:AQ$3="Jumat")*IFERROR(VLOOKUP($C10,DATA_JAM_PELAJARAN!$C:$K,7,0),0)+(ABSENSI!D$3:AQ$3="Sabtu")*IFERROR(VLOOKUP($C10,DATA_JAM_PELAJARAN!$C:$K,8,0),0))) -> 64 | G10: =SUMPRODUCT((ABSENSI!D7:AQ7="Sakit")*((ABSENSI!D$3:AQ$3="Senin")*IFERROR(VLOOKUP($C10,DATA_JAM_PELAJARAN!$C:$K,3,0),0)+(ABSENSI!D$3:AQ$3="Selasa")*IFERROR(VLOOKUP($C10,DATA_JAM_PELAJARAN!$C:$K,4,0),0)+(ABSENSI!D$3:AQ$3="Rabu")*IFERROR(VLOOKUP($C10,DATA_JAM_PELAJARAN!$C:$K,5,0),0)+(ABSENSI!D$3:AQ$3="Kamis")*IFERROR(VLOOKUP($C10,DATA_JAM_PELAJARAN!$C:$K,6,0),0)+(ABSENSI!D$3:AQ$3="Jumat")*IFERROR(VLOOKUP($C10,DATA_JAM_PELAJARAN!$C:$K,7,0),0)+(ABSENSI!D$3:AQ$3="Sabtu")*IFERROR(VLOOKUP($C10,DATA_JAM_PELAJARAN!$C:$K,8,0),0))) -> 0 | H10: =SUMPRODUCT((ABSENSI!D7:AQ7="Izin")*((ABSENSI!D$3:AQ$3="Senin")*IFERROR(VLOOKUP($C10,DATA_JAM_PELAJARAN!$C:$K,3,0),0)+(ABSENSI!D$3:AQ$3="Selasa")*IFERROR(VLOOKUP($C10,DATA_JAM_PELAJARAN!$C:$K,4,0),0)+(ABSENSI!D$3:AQ$3="Rabu")*IFERROR(VLOOKUP($C10,DATA_JAM_PELAJARAN!$C:$K,5,0),0)+(ABSENSI!D$3:AQ$3="Kamis")*IFERROR(VLOOKUP($C10,DATA_JAM_PELAJARAN!$C:$K,6,0),0)+(ABSENSI!D$3:AQ$3="Jumat")*IFERROR(VLOOKUP($C10,DATA_JAM_PELAJARAN!$C:$K,7,0),0)+(ABSENSI!D$3:AQ$3="Sabtu")*IFERROR(VLOOKUP($C10,DATA_JAM_PELAJARAN!$C:$K,8,0),0))) -> 0 | I10: =SUMPRODUCT((ABSENSI!D7:AQ7="Tanpa Keterangan")*((ABSENSI!D$3:AQ$3="Senin")*IFERROR(VLOOKUP($C10,DATA_JAM_PELAJARAN!$C:$K,3,0),0)+(ABSENSI!D$3:AQ$3="Selasa")*IFERROR(VLOOKUP($C10,DATA_JAM_PELAJARAN!$C:$K,4,0),0)+(ABSENSI!D$3:AQ$3="Rabu")*IFERROR(VLOOKUP($C10,DATA_JAM_PELAJARAN!$C:$K,5,0),0)+(ABSENSI!D$3:AQ$3="Kamis")*IFERROR(VLOOKUP($C10,DATA_JAM_PELAJARAN!$C:$K,6,0),0)+(ABSENSI!D$3:AQ$3="Jumat")*IFERROR(VLOOKUP($C10,DATA_JAM_PELAJARAN!$C:$K,7,0),0)+(ABSENSI!D$3:AQ$3="Sabtu")*IFERROR(VLOOKUP($C10,DATA_JAM_PELAJARAN!$C:$K,8,0),0))) -> 0 | J10: =SUM(G10:I10) -> 0 | K10: =COUNTIF(ABSENSI!D7:AQ7,"Mengajar") -> 12 | L10: =COUNTIF(ABSENSI!D7:AQ7,"Sakit") -> 0 | M10: =COUNTIF(ABSENSI!D7:AQ7,"Izin") -> 0 | N10: =COUNTIF(ABSENSI!D7:AQ7,"Tanpa Keterangan") -> 0 | O10: =IFERROR(F10/E10,0) -> 0.88888889 | P10: =SUMPRODUCT((ABSENSI!D$3:AQ$3="Senin")*(IFERROR(VLOOKUP($C10,DATA_JAM_PELAJARAN!$C:$K,3,0),0)>0)+(ABSENSI!D$3:AQ$3="Selasa")*(IFERROR(VLOOKUP($C10,DATA_JAM_PELAJARAN!$C:$K,4,0),0)>0)+(ABSENSI!D$3:AQ$3="Rabu")*(IFERROR(VLOOKUP($C10,DATA_JAM_PELAJARAN!$C:$K,5,0),0)>0)+(ABSENSI!D$3:AQ$3="Kamis")*(IFERROR(VLOOKUP($C10,DATA_JAM_PELAJARAN!$C:$K,6,0),0)>0)+(ABSENSI!D$3:AQ$3="Jumat")*(IFERROR(VLOOKUP($C10,DATA_JAM_PELAJARAN!$C:$K,7,0),0)>0)+(ABSENSI!D$3:AQ$3="Sabtu")*(IFERROR(VLOOKUP($C10,DATA_JAM_PELAJARAN!$C:$K,8,0),0)>0)) -> 13
B11: 5 | C11: Klidia Nurwulan, S.Pd | D11: B. Indonesia | E11: =SUMPRODUCT((ABSENSI!D$3:AQ$3="Senin")*IFERROR(VLOOKUP($C11,DATA_JAM_PELAJARAN!$C:$K,3,0),0)+(ABSENSI!D$3:AQ$3="Selasa")*IFERROR(VLOOKUP($C11,DATA_JAM_PELAJARAN!$C:$K,4,0),0)+(ABSENSI!D$3:AQ$3="Rabu")*IFERROR(VLOOKUP($C11,DATA_JAM_PELAJARAN!$C:$K,5,0),0)+(ABSENSI!D$3:AQ$3="Kamis")*IFERROR(VLOOKUP($C11,DATA_JAM_PELAJARAN!$C:$K,6,0),0)+(ABSENSI!D$3:AQ$3="Jumat")*IFERROR(VLOOKUP($C11,DATA_JAM_PELAJARAN!$C:$K,7,0),0)+(ABSENSI!D$3:AQ$3="Sabtu")*IFERROR(VLOOKUP($C11,DATA_JAM_PELAJARAN!$C:$K,8,0),0)) -> 136 | F11: =SUMPRODUCT((ABSENSI!D8:AQ8="Mengajar")*((ABSENSI!D$3:AQ$3="Senin")*IFERROR(VLOOKUP($C11,DATA_JAM_PELAJARAN!$C:$K,3,0),0)+(ABSENSI!D$3:AQ$3="Selasa")*IFERROR(VLOOKUP($C11,DATA_JAM_PELAJARAN!$C:$K,4,0),0)+(ABSENSI!D$3:AQ$3="Rabu")*IFERROR(VLOOKUP($C11,DATA_JAM_PELAJARAN!$C:$K,5,0),0)+(ABSENSI!D$3:AQ$3="Kamis")*IFERROR(VLOOKUP($C11,DATA_JAM_PELAJARAN!$C:$K,6,0),0)+(ABSENSI!D$3:AQ$3="Jumat")*IFERROR(VLOOKUP($C11,DATA_JAM_PELAJARAN!$C:$K,7,0),0)+(ABSENSI!D$3:AQ$3="Sabtu")*IFERROR(VLOOKUP($C11,DATA_JAM_PELAJARAN!$C:$K,8,0),0))) -> 120 | G11: =SUMPRODUCT((ABSENSI!D8:AQ8="Sakit")*((ABSENSI!D$3:AQ$3="Senin")*IFERROR(VLOOKUP($C11,DATA_JAM_PELAJARAN!$C:$K,3,0),0)+(ABSENSI!D$3:AQ$3="Selasa")*IFERROR(VLOOKUP($C11,DATA_JAM_PELAJARAN!$C:$K,4,0),0)+(ABSENSI!D$3:AQ$3="Rabu")*IFERROR(VLOOKUP($C11,DATA_JAM_PELAJARAN!$C:$K,5,0),0)+(ABSENSI!D$3:AQ$3="Kamis")*IFERROR(VLOOKUP($C11,DATA_JAM_PELAJARAN!$C:$K,6,0),0)+(ABSENSI!D$3:AQ$3="Jumat")*IFERROR(VLOOKUP($C11,DATA_JAM_PELAJARAN!$C:$K,7,0),0)+(ABSENSI!D$3:AQ$3="Sabtu")*IFERROR(VLOOKUP($C11,DATA_JAM_PELAJARAN!$C:$K,8,0),0))) -> 0 | H11: =SUMPRODUCT((ABSENSI!D8:AQ8="Izin")*((ABSENSI!D$3:AQ$3="Senin")*IFERROR(VLOOKUP($C11,DATA_JAM_PELAJARAN!$C:$K,3,0),0)+(ABSENSI!D$3:AQ$3="Selasa")*IFERROR(VLOOKUP($C11,DATA_JAM_PELAJARAN!$C:$K,4,0),0)+(ABSENSI!D$3:AQ$3="Rabu")*IFERROR(VLOOKUP($C11,DATA_JAM_PELAJARAN!$C:$K,5,0),0)+(ABSENSI!D$3:AQ$3="Kamis")*IFERROR(VLOOKUP($C11,DATA_JAM_PELAJARAN!$C:$K,6,0),0)+(ABSENSI!D$3:AQ$3="Jumat")*IFERROR(VLOOKUP($C11,DATA_JAM_PELAJARAN!$C:$K,7,0),0)+(ABSENSI!D$3:AQ$3="Sabtu")*IFERROR(VLOOKUP($C11,DATA_JAM_PELAJARAN!$C:$K,8,0),0))) -> 0 | I11: =SUMPRODUCT((ABSENSI!D8:AQ8="Tanpa Keterangan")*((ABSENSI!D$3:AQ$3="Senin")*IFERROR(VLOOKUP($C11,DATA_JAM_PELAJARAN!$C:$K,3,0),0)+(ABSENSI!D$3:AQ$3="Selasa")*IFERROR(VLOOKUP($C11,DATA_JAM_PELAJARAN!$C:$K,4,0),0)+(ABSENSI!D$3:AQ$3="Rabu")*IFERROR(VLOOKUP($C11,DATA_JAM_PELAJARAN!$C:$K,5,0),0)+(ABSENSI!D$3:AQ$3="Kamis")*IFERROR(VLOOKUP($C11,DATA_JAM_PELAJARAN!$C:$K,6,0),0)+(ABSENSI!D$3:AQ$3="Jumat")*IFERROR(VLOOKUP($C11,DATA_JAM_PELAJARAN!$C:$K,7,0),0)+(ABSENSI!D$3:AQ$3="Sabtu")*IFERROR(VLOOKUP($C11,DATA_JAM_PELAJARAN!$C:$K,8,0),0))) -> 0 | J11: =SUM(G11:I11) -> 0 | K11: =COUNTIF(ABSENSI!D8:AQ8,"Mengajar") -> 16 | L11: =COUNTIF(ABSENSI!D8:AQ8,"Sakit") -> 0 | M11: =COUNTIF(ABSENSI!D8:AQ8,"Izin") -> 0 | N11: =COUNTIF(ABSENSI!D8:AQ8,"Tanpa Keterangan") -> 0 | O11: =IFERROR(F11/E11,0) -> 0.88235294 | P11: =SUMPRODUCT((ABSENSI!D$3:AQ$3="Senin")*(IFERROR(VLOOKUP($C11,DATA_JAM_PELAJARAN!$C:$K,3,0),0)>0)+(ABSENSI!D$3:AQ$3="Selasa")*(IFERROR(VLOOKUP($C11,DATA_JAM_PELAJARAN!$C:$K,4,0),0)>0)+(ABSENSI!D$3:AQ$3="Rabu")*(IFERROR(VLOOKUP($C11,DATA_JAM_PELAJARAN!$C:$K,5,0),0)>0)+(ABSENSI!D$3:AQ$3="Kamis")*(IFERROR(VLOOKUP($C11,DATA_JAM_PELAJARAN!$C:$K,6,0),0)>0)+(ABSENSI!D$3:AQ$3="Jumat")*(IFERROR(VLOOKUP($C11,DATA_JAM_PELAJARAN!$C:$K,7,0),0)>0)+(ABSENSI!D$3:AQ$3="Sabtu")*(IFERROR(VLOOKUP($C11,DATA_JAM_PELAJARAN!$C:$K,8,0),0)>0)) -> 18
B12: 6 | C12: Putri Megawati, S.Pd | D12: PJOK | E12: =SUMPRODUCT((ABSENSI!D$3:AQ$3="Senin")*IFERROR(VLOOKUP($C12,DATA_JAM_PELAJARAN!$C:$K,3,0),0)+(ABSENSI!D$3:AQ$3="Selasa")*IFERROR(VLOOKUP($C12,DATA_JAM_PELAJARAN!$C:$K,4,0),0)+(ABSENSI!D$3:AQ$3="Rabu")*IFERROR(VLOOKUP($C12,DATA_JAM_PELAJARAN!$C:$K,5,0),0)+(ABSENSI!D$3:AQ$3="Kamis")*IFERROR(VLOOKUP($C12,DATA_JAM_PELAJARAN!$C:$K,6,0),0)+(ABSENSI!D$3:AQ$3="Jumat")*IFERROR(VLOOKUP($C12,DATA_JAM_PELAJARAN!$C:$K,7,0),0)+(ABSENSI!D$3:AQ$3="Sabtu")*IFERROR(VLOOKUP($C12,DATA_JAM_PELAJARAN!$C:$K,8,0),0)) -> 69 | F12: =SUMPRODUCT((ABSENSI!D9:AQ9="Mengajar")*((ABSENSI!D$3:AQ$3="Senin")*IFERROR(VLOOKUP($C12,DATA_JAM_PELAJARAN!$C:$K,3,0),0)+(ABSENSI!D$3:AQ$3="Selasa")*IFERROR(VLOOKUP($C12,DATA_JAM_PELAJARAN!$C:$K,4,0),0)+(ABSENSI!D$3:AQ$3="Rabu")*IFERROR(VLOOKUP($C12,DATA_JAM_PELAJARAN!$C:$K,5,0),0)+(ABSENSI!D$3:AQ$3="Kamis")*IFERROR(VLOOKUP($C12,DATA_JAM_PELAJARAN!$C:$K,6,0),0)+(ABSENSI!D$3:AQ$3="Jumat")*IFERROR(VLOOKUP($C12,DATA_JAM_PELAJARAN!$C:$K,7,0),0)+(ABSENSI!D$3:AQ$3="Sabtu")*IFERROR(VLOOKUP($C12,DATA_JAM_PELAJARAN!$C:$K,8,0),0))) -> 60 | G12: =SUMPRODUCT((ABSENSI!D9:AQ9="Sakit")*((ABSENSI!D$3:AQ$3="Senin")*IFERROR(VLOOKUP($C12,DATA_JAM_PELAJARAN!$C:$K,3,0),0)+(ABSENSI!D$3:AQ$3="Selasa")*IFERROR(VLOOKUP($C12,DATA_JAM_PELAJARAN!$C:$K,4,0),0)+(ABSENSI!D$3:AQ$3="Rabu")*IFERROR(VLOOKUP($C12,DATA_JAM_PELAJARAN!$C:$K,5,0),0)+(ABSENSI!D$3:AQ$3="Kamis")*IFERROR(VLOOKUP($C12,DATA_JAM_PELAJARAN!$C:$K,6,0),0)+(ABSENSI!D$3:AQ$3="Jumat")*IFERROR(VLOOKUP($C12,DATA_JAM_PELAJARAN!$C:$K,7,0),0)+(ABSENSI!D$3:AQ$3="Sabtu")*IFERROR(VLOOKUP($C12,DATA_JAM_PELAJARAN!$C:$K,8,0),0))) -> 0 | H12: =SUMPRODUCT((ABSENSI!D9:AQ9="Izin")*((ABSENSI!D$3:AQ$3="Senin")*IFERROR(VLOOKUP($C12,DATA_JAM_PELAJARAN!$C:$K,3,0),0)+(ABSENSI!D$3:AQ$3="Selasa")*IFERROR(VLOOKUP($C12,DATA_JAM_PELAJARAN!$C:$K,4,0),0)+(ABSENSI!D$3:AQ$3="Rabu")*IFERROR(VLOOKUP($C12,DATA_JAM_PELAJARAN!$C:$K,5,0),0)+(ABSENSI!D$3:AQ$3="Kamis")*IFERROR(VLOOKUP($C12,DATA_JAM_PELAJARAN!$C:$K,6,0),0)+(ABSENSI!D$3:AQ$3="Jumat")*IFERROR(VLOOKUP($C12,DATA_JAM_PELAJARAN!$C:$K,7,0),0)+(ABSENSI!D$3:AQ$3="Sabtu")*IFERROR(VLOOKUP($C12,DATA_JAM_PELAJARAN!$C:$K,8,0),0))) -> 0 | I12: =SUMPRODUCT((ABSENSI!D9:AQ9="Tanpa Keterangan")*((ABSENSI!D$3:AQ$3="Senin")*IFERROR(VLOOKUP($C12,DATA_JAM_PELAJARAN!$C:$K,3,0),0)+(ABSENSI!D$3:AQ$3="Selasa")*IFERROR(VLOOKUP($C12,DATA_JAM_PELAJARAN!$C:$K,4,0),0)+(ABSENSI!D$3:AQ$3="Rabu")*IFERROR(VLOOKUP($C12,DATA_JAM_PELAJARAN!$C:$K,5,0),0)+(ABSENSI!D$3:AQ$3="Kamis")*IFERROR(VLOOKUP($C12,DATA_JAM_PELAJARAN!$C:$K,6,0),0)+(ABSENSI!D$3:AQ$3="Jumat")*IFERROR(VLOOKUP($C12,DATA_JAM_PELAJARAN!$C:$K,7,0),0)+(ABSENSI!D$3:AQ$3="Sabtu")*IFERROR(VLOOKUP($C12,DATA_JAM_PELAJARAN!$C:$K,8,0),0))) -> 0 | J12: =SUM(G12:I12) -> 0 | K12: =COUNTIF(ABSENSI!D9:AQ9,"Mengajar") -> 12 | L12: =COUNTIF(ABSENSI!D9:AQ9,"Sakit") -> 0 | M12: =COUNTIF(ABSENSI!D9:AQ9,"Izin") -> 0 | N12: =COUNTIF(ABSENSI!D9:AQ9,"Tanpa Keterangan") -> 0 | O12: =IFERROR(F12/E12,0) -> 0.86956522 | P12: =SUMPRODUCT((ABSENSI!D$3:AQ$3="Senin")*(IFERROR(VLOOKUP($C12,DATA_JAM_PELAJARAN!$C:$K,3,0),0)>0)+(ABSENSI!D$3:AQ$3="Selasa")*(IFERROR(VLOOKUP($C12,DATA_JAM_PELAJARAN!$C:$K,4,0),0)>0)+(ABSENSI!D$3:AQ$3="Rabu")*(IFERROR(VLOOKUP($C12,DATA_JAM_PELAJARAN!$C:$K,5,0),0)>0)+(ABSENSI!D$3:AQ$3="Kamis")*(IFERROR(VLOOKUP($C12,DATA_JAM_PELAJARAN!$C:$K,6,0),0)>0)+(ABSENSI!D$3:AQ$3="Jumat")*(IFERROR(VLOOKUP($C12,DATA_JAM_PELAJARAN!$C:$K,7,0),0)>0)+(ABSENSI!D$3:AQ$3="Sabtu")*(IFERROR(VLOOKUP($C12,DATA_JAM_PELAJARAN!$C:$K,8,0),0)>0)) -> 14
B13: 7 | C13: Dani Ramdhani, S.Pd | D13: B. Inggris | E13: =SUMPRODUCT((ABSENSI!D$3:AQ$3="Senin")*IFERROR(VLOOKUP($C13,DATA_JAM_PELAJARAN!$C:$K,3,0),0)+(ABSENSI!D$3:AQ$3="Selasa")*IFERROR(VLOOKUP($C13,DATA_JAM_PELAJARAN!$C:$K,4,0),0)+(ABSENSI!D$3:AQ$3="Rabu")*IFERROR(VLOOKUP($C13,DATA_JAM_PELAJARAN!$C:$K,5,0),0)+(ABSENSI!D$3:AQ$3="Kamis")*IFERROR(VLOOKUP($C13,DATA_JAM_PELAJARAN!$C:$K,6,0),0)+(ABSENSI!D$3:AQ$3="Jumat")*IFERROR(VLOOKUP($C13,DATA_JAM_PELAJARAN!$C:$K,7,0),0)+(ABSENSI!D$3:AQ$3="Sabtu")*IFERROR(VLOOKUP($C13,DATA_JAM_PELAJARAN!$C:$K,8,0),0)) -> 56 | F13: =SUMPRODUCT((ABSENSI!D10:AQ10="Mengajar")*((ABSENSI!D$3:AQ$3="Senin")*IFERROR(VLOOKUP($C13,DATA_JAM_PELAJARAN!$C:$K,3,0),0)+(ABSENSI!D$3:AQ$3="Selasa")*IFERROR(VLOOKUP($C13,DATA_JAM_PELAJARAN!$C:$K,4,0),0)+(ABSENSI!D$3:AQ$3="Rabu")*IFERROR(VLOOKUP($C13,DATA_JAM_PELAJARAN!$C:$K,5,0),0)+(ABSENSI!D$3:AQ$3="Kamis")*IFERROR(VLOOKUP($C13,DATA_JAM_PELAJARAN!$C:$K,6,0),0)+(ABSENSI!D$3:AQ$3="Jumat")*IFERROR(VLOOKUP($C13,DATA_JAM_PELAJARAN!$C:$K,7,0),0)+(ABSENSI!D$3:AQ$3="Sabtu")*IFERROR(VLOOKUP($C13,DATA_JAM_PELAJARAN!$C:$K,8,0),0))) -> 48 | G13: =SUMPRODUCT((ABSENSI!D10:AQ10="Sakit")*((ABSENSI!D$3:AQ$3="Senin")*IFERROR(VLOOKUP($C13,DATA_JAM_PELAJARAN!$C:$K,3,0),0)+(ABSENSI!D$3:AQ$3="Selasa")*IFERROR(VLOOKUP($C13,DATA_JAM_PELAJARAN!$C:$K,4,0),0)+(ABSENSI!D$3:AQ$3="Rabu")*IFERROR(VLOOKUP($C13,DATA_JAM_PELAJARAN!$C:$K,5,0),0)+(ABSENSI!D$3:AQ$3="Kamis")*IFERROR(VLOOKUP($C13,DATA_JAM_PELAJARAN!$C:$K,6,0),0)+(ABSENSI!D$3:AQ$3="Jumat")*IFERROR(VLOOKUP($C13,DATA_JAM_PELAJARAN!$C:$K,7,0),0)+(ABSENSI!D$3:AQ$3="Sabtu")*IFERROR(VLOOKUP($C13,DATA_JAM_PELAJARAN!$C:$K,8,0),0))) -> 0 | H13: =SUMPRODUCT((ABSENSI!D10:AQ10="Izin")*((ABSENSI!D$3:AQ$3="Senin")*IFERROR(VLOOKUP($C13,DATA_JAM_PELAJARAN!$C:$K,3,0),0)+(ABSENSI!D$3:AQ$3="Selasa")*IFERROR(VLOOKUP($C13,DATA_JAM_PELAJARAN!$C:$K,4,0),0)+(ABSENSI!D$3:AQ$3="Rabu")*IFERROR(VLOOKUP($C13,DATA_JAM_PELAJARAN!$C:$K,5,0),0)+(ABSENSI!D$3:AQ$3="Kamis")*IFERROR(VLOOKUP($C13,DATA_JAM_PELAJARAN!$C:$K,6,0),0)+(ABSENSI!D$3:AQ$3="Jumat")*IFERROR(VLOOKUP($C13,DATA_JAM_PELAJARAN!$C:$K,7,0),0)+(ABSENSI!D$3:AQ$3="Sabtu")*IFERROR(VLOOKUP($C13,DATA_JAM_PELAJARAN!$C:$K,8,0),0))) -> 0 | I13: =SUMPRODUCT((ABSENSI!D10:AQ10="Tanpa Keterangan")*((ABSENSI!D$3:AQ$3="Senin")*IFERROR(VLOOKUP($C13,DATA_JAM_PELAJARAN!$C:$K,3,0),0)+(ABSENSI!D$3:AQ$3="Selasa")*IFERROR(VLOOKUP($C13,DATA_JAM_PELAJARAN!$C:$K,4,0),0)+(ABSENSI!D$3:AQ$3="Rabu")*IFERROR(VLOOKUP($C13,DATA_JAM_PELAJARAN!$C:$K,5,0),0)+(ABSENSI!D$3:AQ$3="Kamis")*IFERROR(VLOOKUP($C13,DATA_JAM_PELAJARAN!$C:$K,6,0),0)+(ABSENSI!D$3:AQ$3="Jumat")*IFERROR(VLOOKUP($C13,DATA_JAM_PELAJARAN!$C:$K,7,0),0)+(ABSENSI!D$3:AQ$3="Sabtu")*IFERROR(VLOOKUP($C13,DATA_JAM_PELAJARAN!$C:$K,8,0),0))) -> 0 | J13: =SUM(G13:I13) -> 0 | K13: =COUNTIF(ABSENSI!D10:AQ10,"Mengajar") -> 12 | L13: =COUNTIF(ABSENSI!D10:AQ10,"Sakit") -> 0 | M13: =COUNTIF(ABSENSI!D10:AQ10,"Izin") -> 0 | N13: =COUNTIF(ABSENSI!D10:AQ10,"Tanpa Keterangan") -> 0 | O13: =IFERROR(F13/E13,0) -> 0.85714286 | P13: =SUMPRODUCT((ABSENSI!D$3:AQ$3="Senin")*(IFERROR(VLOOKUP($C13,DATA_JAM_PELAJARAN!$C:$K,3,0),0)>0)+(ABSENSI!D$3:AQ$3="Selasa")*(IFERROR(VLOOKUP($C13,DATA_JAM_PELAJARAN!$C:$K,4,0),0)>0)+(ABSENSI!D$3:AQ$3="Rabu")*(IFERROR(VLOOKUP($C13,DATA_JAM_PELAJARAN!$C:$K,5,0),0)>0)+(ABSENSI!D$3:AQ$3="Kamis")*(IFERROR(VLOOKUP($C13,DATA_JAM_PELAJARAN!$C:$K,6,0),0)>0)+(ABSENSI!D$3:AQ$3="Jumat")*(IFERROR(VLOOKUP($C13,DATA_JAM_PELAJARAN!$C:$K,7,0),0)>0)+(ABSENSI!D$3:AQ$3="Sabtu")*(IFERROR(VLOOKUP($C13,DATA_JAM_PELAJARAN!$C:$K,8,0),0)>0)) -> 14
B14: 8 | C14: Shafa Padilah S. S.Pd | D14: B. Indonesia | E14: =SUMPRODUCT((ABSENSI!D$3:AQ$3="Senin")*IFERROR(VLOOKUP($C14,DATA_JAM_PELAJARAN!$C:$K,3,0),0)+(ABSENSI!D$3:AQ$3="Selasa")*IFERROR(VLOOKUP($C14,DATA_JAM_PELAJARAN!$C:$K,4,0),0)+(ABSENSI!D$3:AQ$3="Rabu")*IFERROR(VLOOKUP($C14,DATA_JAM_PELAJARAN!$C:$K,5,0),0)+(ABSENSI!D$3:AQ$3="Kamis")*IFERROR(VLOOKUP($C14,DATA_JAM_PELAJARAN!$C:$K,6,0),0)+(ABSENSI!D$3:AQ$3="Jumat")*IFERROR(VLOOKUP($C14,DATA_JAM_PELAJARAN!$C:$K,7,0),0)+(ABSENSI!D$3:AQ$3="Sabtu")*IFERROR(VLOOKUP($C14,DATA_JAM_PELAJARAN!$C:$K,8,0),0)) -> 111 | F14: =SUMPRODUCT((ABSENSI!D11:AQ11="Mengajar")*((ABSENSI!D$3:AQ$3="Senin")*IFERROR(VLOOKUP($C14,DATA_JAM_PELAJARAN!$C:$K,3,0),0)+(ABSENSI!D$3:AQ$3="Selasa")*IFERROR(VLOOKUP($C14,DATA_JAM_PELAJARAN!$C:$K,4,0),0)+(ABSENSI!D$3:AQ$3="Rabu")*IFERROR(VLOOKUP($C14,DATA_JAM_PELAJARAN!$C:$K,5,0),0)+(ABSENSI!D$3:AQ$3="Kamis")*IFERROR(VLOOKUP($C14,DATA_JAM_PELAJARAN!$C:$K,6,0),0)+(ABSENSI!D$3:AQ$3="Jumat")*IFERROR(VLOOKUP($C14,DATA_JAM_PELAJARAN!$C:$K,7,0),0)+(ABSENSI!D$3:AQ$3="Sabtu")*IFERROR(VLOOKUP($C14,DATA_JAM_PELAJARAN!$C:$K,8,0),0))) -> 100 | G14: =SUMPRODUCT((ABSENSI!D11:AQ11="Sakit")*((ABSENSI!D$3:AQ$3="Senin")*IFERROR(VLOOKUP($C14,DATA_JAM_PELAJARAN!$C:$K,3,0),0)+(ABSENSI!D$3:AQ$3="Selasa")*IFERROR(VLOOKUP($C14,DATA_JAM_PELAJARAN!$C:$K,4,0),0)+(ABSENSI!D$3:AQ$3="Rabu")*IFERROR(VLOOKUP($C14,DATA_JAM_PELAJARAN!$C:$K,5,0),0)+(ABSENSI!D$3:AQ$3="Kamis")*IFERROR(VLOOKUP($C14,DATA_JAM_PELAJARAN!$C:$K,6,0),0)+(ABSENSI!D$3:AQ$3="Jumat")*IFERROR(VLOOKUP($C14,DATA_JAM_PELAJARAN!$C:$K,7,0),0)+(ABSENSI!D$3:AQ$3="Sabtu")*IFERROR(VLOOKUP($C14,DATA_JAM_PELAJARAN!$C:$K,8,0),0))) -> 0 | H14: =SUMPRODUCT((ABSENSI!D11:AQ11="Izin")*((ABSENSI!D$3:AQ$3="Senin")*IFERROR(VLOOKUP($C14,DATA_JAM_PELAJARAN!$C:$K,3,0),0)+(ABSENSI!D$3:AQ$3="Selasa")*IFERROR(VLOOKUP($C14,DATA_JAM_PELAJARAN!$C:$K,4,0),0)+(ABSENSI!D$3:AQ$3="Rabu")*IFERROR(VLOOKUP($C14,DATA_JAM_PELAJARAN!$C:$K,5,0),0)+(ABSENSI!D$3:AQ$3="Kamis")*IFERROR(VLOOKUP($C14,DATA_JAM_PELAJARAN!$C:$K,6,0),0)+(ABSENSI!D$3:AQ$3="Jumat")*IFERROR(VLOOKUP($C14,DATA_JAM_PELAJARAN!$C:$K,7,0),0)+(ABSENSI!D$3:AQ$3="Sabtu")*IFERROR(VLOOKUP($C14,DATA_JAM_PELAJARAN!$C:$K,8,0),0))) -> 0 | I14: =SUMPRODUCT((ABSENSI!D11:AQ11="Tanpa Keterangan")*((ABSENSI!D$3:AQ$3="Senin")*IFERROR(VLOOKUP($C14,DATA_JAM_PELAJARAN!$C:$K,3,0),0)+(ABSENSI!D$3:AQ$3="Selasa")*IFERROR(VLOOKUP($C14,DATA_JAM_PELAJARAN!$C:$K,4,0),0)+(ABSENSI!D$3:AQ$3="Rabu")*IFERROR(VLOOKUP($C14,DATA_JAM_PELAJARAN!$C:$K,5,0),0)+(ABSENSI!D$3:AQ$3="Kamis")*IFERROR(VLOOKUP($C14,DATA_JAM_PELAJARAN!$C:$K,6,0),0)+(ABSENSI!D$3:AQ$3="Jumat")*IFERROR(VLOOKUP($C14,DATA_JAM_PELAJARAN!$C:$K,7,0),0)+(ABSENSI!D$3:AQ$3="Sabtu")*IFERROR(VLOOKUP($C14,DATA_JAM_PELAJARAN!$C:$K,8,0),0))) -> 0 | J14: =SUM(G14:I14) -> 0 | K14: =COUNTIF(ABSENSI!D11:AQ11,"Mengajar") -> 16 | L14: =COUNTIF(ABSENSI!D11:AQ11,"Sakit") -> 0 | M14: =COUNTIF(ABSENSI!D11:AQ11,"Izin") -> 0 | N14: =COUNTIF(ABSENSI!D11:AQ11,"Tanpa Keterangan") -> 0 | O14: =IFERROR(F14/E14,0) -> 0.9009009 | P14: =SUMPRODUCT((ABSENSI!D$3:AQ$3="Senin")*(IFERROR(VLOOKUP($C14,DATA_JAM_PELAJARAN!$C:$K,3,0),0)>0)+(ABSENSI!D$3:AQ$3="Selasa")*(IFERROR(VLOOKUP($C14,DATA_JAM_PELAJARAN!$C:$K,4,0),0)>0)+(ABSENSI!D$3:AQ$3="Rabu")*(IFERROR(VLOOKUP($C14,DATA_JAM_PELAJARAN!$C:$K,5,0),0)>0)+(ABSENSI!D$3:AQ$3="Kamis")*(IFERROR(VLOOKUP($C14,DATA_JAM_PELAJARAN!$C:$K,6,0),0)>0)+(ABSENSI!D$3:AQ$3="Jumat")*(IFERROR(VLOOKUP($C14,DATA_JAM_PELAJARAN!$C:$K,7,0),0)>0)+(ABSENSI!D$3:AQ$3="Sabtu")*(IFERROR(VLOOKUP($C14,DATA_JAM_PELAJARAN!$C:$K,8,0),0)>0)) -> 18
B15: 9 | C15: Imam Hasbulloh, S.Pd | D15: Matematika | E15: =SUMPRODUCT((ABSENSI!D$3:AQ$3="Senin")*IFERROR(VLOOKUP($C15,DATA_JAM_PELAJARAN!$C:$K,3,0),0)+(ABSENSI!D$3:AQ$3="Selasa")*IFERROR(VLOOKUP($C15,DATA_JAM_PELAJARAN!$C:$K,4,0),0)+(ABSENSI!D$3:AQ$3="Rabu")*IFERROR(VLOOKUP($C15,DATA_JAM_PELAJARAN!$C:$K,5,0),0)+(ABSENSI!D$3:AQ$3="Kamis")*IFERROR(VLOOKUP($C15,DATA_JAM_PELAJARAN!$C:$K,6,0),0)+(ABSENSI!D$3:AQ$3="Jumat")*IFERROR(VLOOKUP($C15,DATA_JAM_PELAJARAN!$C:$K,7,0),0)+(ABSENSI!D$3:AQ$3="Sabtu")*IFERROR(VLOOKUP($C15,DATA_JAM_PELAJARAN!$C:$K,8,0),0)) -> 161 | F15: =SUMPRODUCT((ABSENSI!D12:AQ12="Mengajar")*((ABSENSI!D$3:AQ$3="Senin")*IFERROR(VLOOKUP($C15,DATA_JAM_PELAJARAN!$C:$K,3,0),0)+(ABSENSI!D$3:AQ$3="Selasa")*IFERROR(VLOOKUP($C15,DATA_JAM_PELAJARAN!$C:$K,4,0),0)+(ABSENSI!D$3:AQ$3="Rabu")*IFERROR(VLOOKUP($C15,DATA_JAM_PELAJARAN!$C:$K,5,0),0)+(ABSENSI!D$3:AQ$3="Kamis")*IFERROR(VLOOKUP($C15,DATA_JAM_PELAJARAN!$C:$K,6,0),0)+(ABSENSI!D$3:AQ$3="Jumat")*IFERROR(VLOOKUP($C15,DATA_JAM_PELAJARAN!$C:$K,7,0),0)+(ABSENSI!D$3:AQ$3="Sabtu")*IFERROR(VLOOKUP($C15,DATA_JAM_PELAJARAN!$C:$K,8,0),0))) -> 140 | G15: =SUMPRODUCT((ABSENSI!D12:AQ12="Sakit")*((ABSENSI!D$3:AQ$3="Senin")*IFERROR(VLOOKUP($C15,DATA_JAM_PELAJARAN!$C:$K,3,0),0)+(ABSENSI!D$3:AQ$3="Selasa")*IFERROR(VLOOKUP($C15,DATA_JAM_PELAJARAN!$C:$K,4,0),0)+(ABSENSI!D$3:AQ$3="Rabu")*IFERROR(VLOOKUP($C15,DATA_JAM_PELAJARAN!$C:$K,5,0),0)+(ABSENSI!D$3:AQ$3="Kamis")*IFERROR(VLOOKUP($C15,DATA_JAM_PELAJARAN!$C:$K,6,0),0)+(ABSENSI!D$3:AQ$3="Jumat")*IFERROR(VLOOKUP($C15,DATA_JAM_PELAJARAN!$C:$K,7,0),0)+(ABSENSI!D$3:AQ$3="Sabtu")*IFERROR(VLOOKUP($C15,DATA_JAM_PELAJARAN!$C:$K,8,0),0))) -> 0 | H15: =SUMPRODUCT((ABSENSI!D12:AQ12="Izin")*((ABSENSI!D$3:AQ$3="Senin")*IFERROR(VLOOKUP($C15,DATA_JAM_PELAJARAN!$C:$K,3,0),0)+(ABSENSI!D$3:AQ$3="Selasa")*IFERROR(VLOOKUP($C15,DATA_JAM_PELAJARAN!$C:$K,4,0),0)+(ABSENSI!D$3:AQ$3="Rabu")*IFERROR(VLOOKUP($C15,DATA_JAM_PELAJARAN!$C:$K,5,0),0)+(ABSENSI!D$3:AQ$3="Kamis")*IFERROR(VLOOKUP($C15,DATA_JAM_PELAJARAN!$C:$K,6,0),0)+(ABSENSI!D$3:AQ$3="Jumat")*IFERROR(VLOOKUP($C15,DATA_JAM_PELAJARAN!$C:$K,7,0),0)+(ABSENSI!D$3:AQ$3="Sabtu")*IFERROR(VLOOKUP($C15,DATA_JAM_PELAJARAN!$C:$K,8,0),0))) -> 0 | I15: =SUMPRODUCT((ABSENSI!D12:AQ12="Tanpa Keterangan")*((ABSENSI!D$3:AQ$3="Senin")*IFERROR(VLOOKUP($C15,DATA_JAM_PELAJARAN!$C:$K,3,0),0)+(ABSENSI!D$3:AQ$3="Selasa")*IFERROR(VLOOKUP($C15,DATA_JAM_PELAJARAN!$C:$K,4,0),0)+(ABSENSI!D$3:AQ$3="Rabu")*IFERROR(VLOOKUP($C15,DATA_JAM_PELAJARAN!$C:$K,5,0),0)+(ABSENSI!D$3:AQ$3="Kamis")*IFERROR(VLOOKUP($C15,DATA_JAM_PELAJARAN!$C:$K,6,0),0)+(ABSENSI!D$3:AQ$3="Jumat")*IFERROR(VLOOKUP($C15,DATA_JAM_PELAJARAN!$C:$K,7,0),0)+(ABSENSI!D$3:AQ$3="Sabtu")*IFERROR(VLOOKUP($C15,DATA_JAM_PELAJARAN!$C:$K,8,0),0))) -> 0 | J15: =SUM(G15:I15) -> 0 | K15: =COUNTIF(ABSENSI!D12:AQ12,"Mengajar") -> 20 | L15: =COUNTIF(ABSENSI!D12:AQ12,"Sakit") -> 0 | M15: =COUNTIF(ABSENSI!D12:AQ12,"Izin") -> 0 | N15: =COUNTIF(ABSENSI!D12:AQ12,"Tanpa Keterangan") -> 0 | O15: =IFERROR(F15/E15,0) -> 0.86956522 | P15: =SUMPRODUCT((ABSENSI!D$3:AQ$3="Senin")*(IFERROR(VLOOKUP($C15,DATA_JAM_PELAJARAN!$C:$K,3,0),0)>0)+(ABSENSI!D$3:AQ$3="Selasa")*(IFERROR(VLOOKUP($C15,DATA_JAM_PELAJARAN!$C:$K,4,0),0)>0)+(ABSENSI!D$3:AQ$3="Rabu")*(IFERROR(VLOOKUP($C15,DATA_JAM_PELAJARAN!$C:$K,5,0),0)>0)+(ABSENSI!D$3:AQ$3="Kamis")*(IFERROR(VLOOKUP($C15,DATA_JAM_PELAJARAN!$C:$K,6,0),0)>0)+(ABSENSI!D$3:AQ$3="Jumat")*(IFERROR(VLOOKUP($C15,DATA_JAM_PELAJARAN!$C:$K,7,0),0)>0)+(ABSENSI!D$3:AQ$3="Sabtu")*(IFERROR(VLOOKUP($C15,DATA_JAM_PELAJARAN!$C:$K,8,0),0)>0)) -> 23
B16: 10 | C16: Muhamad Aldiansyah | D16: B. Inggris | E16: =SUMPRODUCT((ABSENSI!D$3:AQ$3="Senin")*IFERROR(VLOOKUP($C16,DATA_JAM_PELAJARAN!$C:$K,3,0),0)+(ABSENSI!D$3:AQ$3="Selasa")*IFERROR(VLOOKUP($C16,DATA_JAM_PELAJARAN!$C:$K,4,0),0)+(ABSENSI!D$3:AQ$3="Rabu")*IFERROR(VLOOKUP($C16,DATA_JAM_PELAJARAN!$C:$K,5,0),0)+(ABSENSI!D$3:AQ$3="Kamis")*IFERROR(VLOOKUP($C16,DATA_JAM_PELAJARAN!$C:$K,6,0),0)+(ABSENSI!D$3:AQ$3="Jumat")*IFERROR(VLOOKUP($C16,DATA_JAM_PELAJARAN!$C:$K,7,0),0)+(ABSENSI!D$3:AQ$3="Sabtu")*IFERROR(VLOOKUP($C16,DATA_JAM_PELAJARAN!$C:$K,8,0),0)) -> 74 | F16: =SUMPRODUCT((ABSENSI!D13:AQ13="Mengajar")*((ABSENSI!D$3:AQ$3="Senin")*IFERROR(VLOOKUP($C16,DATA_JAM_PELAJARAN!$C:$K,3,0),0)+(ABSENSI!D$3:AQ$3="Selasa")*IFERROR(VLOOKUP($C16,DATA_JAM_PELAJARAN!$C:$K,4,0),0)+(ABSENSI!D$3:AQ$3="Rabu")*IFERROR(VLOOKUP($C16,DATA_JAM_PELAJARAN!$C:$K,5,0),0)+(ABSENSI!D$3:AQ$3="Kamis")*IFERROR(VLOOKUP($C16,DATA_JAM_PELAJARAN!$C:$K,6,0),0)+(ABSENSI!D$3:AQ$3="Jumat")*IFERROR(VLOOKUP($C16,DATA_JAM_PELAJARAN!$C:$K,7,0),0)+(ABSENSI!D$3:AQ$3="Sabtu")*IFERROR(VLOOKUP($C16,DATA_JAM_PELAJARAN!$C:$K,8,0),0))) -> 64 | G16: =SUMPRODUCT((ABSENSI!D13:AQ13="Sakit")*((ABSENSI!D$3:AQ$3="Senin")*IFERROR(VLOOKUP($C16,DATA_JAM_PELAJARAN!$C:$K,3,0),0)+(ABSENSI!D$3:AQ$3="Selasa")*IFERROR(VLOOKUP($C16,DATA_JAM_PELAJARAN!$C:$K,4,0),0)+(ABSENSI!D$3:AQ$3="Rabu")*IFERROR(VLOOKUP($C16,DATA_JAM_PELAJARAN!$C:$K,5,0),0)+(ABSENSI!D$3:AQ$3="Kamis")*IFERROR(VLOOKUP($C16,DATA_JAM_PELAJARAN!$C:$K,6,0),0)+(ABSENSI!D$3:AQ$3="Jumat")*IFERROR(VLOOKUP($C16,DATA_JAM_PELAJARAN!$C:$K,7,0),0)+(ABSENSI!D$3:AQ$3="Sabtu")*IFERROR(VLOOKUP($C16,DATA_JAM_PELAJARAN!$C:$K,8,0),0))) -> 0 | H16: =SUMPRODUCT((ABSENSI!D13:AQ13="Izin")*((ABSENSI!D$3:AQ$3="Senin")*IFERROR(VLOOKUP($C16,DATA_JAM_PELAJARAN!$C:$K,3,0),0)+(ABSENSI!D$3:AQ$3="Selasa")*IFERROR(VLOOKUP($C16,DATA_JAM_PELAJARAN!$C:$K,4,0),0)+(ABSENSI!D$3:AQ$3="Rabu")*IFERROR(VLOOKUP($C16,DATA_JAM_PELAJARAN!$C:$K,5,0),0)+(ABSENSI!D$3:AQ$3="Kamis")*IFERROR(VLOOKUP($C16,DATA_JAM_PELAJARAN!$C:$K,6,0),0)+(ABSENSI!D$3:AQ$3="Jumat")*IFERROR(VLOOKUP($C16,DATA_JAM_PELAJARAN!$C:$K,7,0),0)+(ABSENSI!D$3:AQ$3="Sabtu")*IFERROR(VLOOKUP($C16,DATA_JAM_PELAJARAN!$C:$K,8,0),0))) -> 0 | I16: =SUMPRODUCT((ABSENSI!D13:AQ13="Tanpa Keterangan")*((ABSENSI!D$3:AQ$3="Senin")*IFERROR(VLOOKUP($C16,DATA_JAM_PELAJARAN!$C:$K,3,0),0)+(ABSENSI!D$3:AQ$3="Selasa")*IFERROR(VLOOKUP($C16,DATA_JAM_PELAJARAN!$C:$K,4,0),0)+(ABSENSI!D$3:AQ$3="Rabu")*IFERROR(VLOOKUP($C16,DATA_JAM_PELAJARAN!$C:$K,5,0),0)+(ABSENSI!D$3:AQ$3="Kamis")*IFERROR(VLOOKUP($C16,DATA_JAM_PELAJARAN!$C:$K,6,0),0)+(ABSENSI!D$3:AQ$3="Jumat")*IFERROR(VLOOKUP($C16,DATA_JAM_PELAJARAN!$C:$K,7,0),0)+(ABSENSI!D$3:AQ$3="Sabtu")*IFERROR(VLOOKUP($C16,DATA_JAM_PELAJARAN!$C:$K,8,0),0))) -> 0 | J16: =SUM(G16:I16) -> 0 | K16: =COUNTIF(ABSENSI!D13:AQ13,"Mengajar") -> 16 | L16: =COUNTIF(ABSENSI!D13:AQ13,"Sakit") -> 0 | M16: =COUNTIF(ABSENSI!D13:AQ13,"Izin") -> 0 | N16: =COUNTIF(ABSENSI!D13:AQ13,"Tanpa Keterangan") -> 0 | O16: =IFERROR(F16/E16,0) -> 0.86486486 | P16: =SUMPRODUCT((ABSENSI!D$3:AQ$3="Senin")*(IFERROR(VLOOKUP($C16,DATA_JAM_PELAJARAN!$C:$K,3,0),0)>0)+(ABSENSI!D$3:AQ$3="Selasa")*(IFERROR(VLOOKUP($C16,DATA_JAM_PELAJARAN!$C:$K,4,0),0)>0)+(ABSENSI!D$3:AQ$3="Rabu")*(IFERROR(VLOOKUP($C16,DATA_JAM_PELAJARAN!$C:$K,5,0),0)>0)+(ABSENSI!D$3:AQ$3="Kamis")*(IFERROR(VLOOKUP($C16,DATA_JAM_PELAJARAN!$C:$K,6,0),0)>0)+(ABSENSI!D$3:AQ$3="Jumat")*(IFERROR(VLOOKUP($C16,DATA_JAM_PELAJARAN!$C:$K,7,0),0)>0)+(ABSENSI!D$3:AQ$3="Sabtu")*(IFERROR(VLOOKUP($C16,DATA_JAM_PELAJARAN!$C:$K,8,0),0)>0)) -> 18
B17: 11 | C17: M. Fadilah Abdurahman | D17: Seni Budaya | E17: =SUMPRODUCT((ABSENSI!D$3:AQ$3="Senin")*IFERROR(VLOOKUP($C17,DATA_JAM_PELAJARAN!$C:$K,3,0),0)+(ABSENSI!D$3:AQ$3="Selasa")*IFERROR(VLOOKUP($C17,DATA_JAM_PELAJARAN!$C:$K,4,0),0)+(ABSENSI!D$3:AQ$3="Rabu")*IFERROR(VLOOKUP($C17,DATA_JAM_PELAJARAN!$C:$K,5,0),0)+(ABSENSI!D$3:AQ$3="Kamis")*IFERROR(VLOOKUP($C17,DATA_JAM_PELAJARAN!$C:$K,6,0),0)+(ABSENSI!D$3:AQ$3="Jumat")*IFERROR(VLOOKUP($C17,DATA_JAM_PELAJARAN!$C:$K,7,0),0)+(ABSENSI!D$3:AQ$3="Sabtu")*IFERROR(VLOOKUP($C17,DATA_JAM_PELAJARAN!$C:$K,8,0),0)) -> 77 | F17: =SUMPRODUCT((ABSENSI!D14:AQ14="Mengajar")*((ABSENSI!D$3:AQ$3="Senin")*IFERROR(VLOOKUP($C17,DATA_JAM_PELAJARAN!$C:$K,3,0),0)+(ABSENSI!D$3:AQ$3="Selasa")*IFERROR(VLOOKUP($C17,DATA_JAM_PELAJARAN!$C:$K,4,0),0)+(ABSENSI!D$3:AQ$3="Rabu")*IFERROR(VLOOKUP($C17,DATA_JAM_PELAJARAN!$C:$K,5,0),0)+(ABSENSI!D$3:AQ$3="Kamis")*IFERROR(VLOOKUP($C17,DATA_JAM_PELAJARAN!$C:$K,6,0),0)+(ABSENSI!D$3:AQ$3="Jumat")*IFERROR(VLOOKUP($C17,DATA_JAM_PELAJARAN!$C:$K,7,0),0)+(ABSENSI!D$3:AQ$3="Sabtu")*IFERROR(VLOOKUP($C17,DATA_JAM_PELAJARAN!$C:$K,8,0),0))) -> 64 | G17: =SUMPRODUCT((ABSENSI!D14:AQ14="Sakit")*((ABSENSI!D$3:AQ$3="Senin")*IFERROR(VLOOKUP($C17,DATA_JAM_PELAJARAN!$C:$K,3,0),0)+(ABSENSI!D$3:AQ$3="Selasa")*IFERROR(VLOOKUP($C17,DATA_JAM_PELAJARAN!$C:$K,4,0),0)+(ABSENSI!D$3:AQ$3="Rabu")*IFERROR(VLOOKUP($C17,DATA_JAM_PELAJARAN!$C:$K,5,0),0)+(ABSENSI!D$3:AQ$3="Kamis")*IFERROR(VLOOKUP($C17,DATA_JAM_PELAJARAN!$C:$K,6,0),0)+(ABSENSI!D$3:AQ$3="Jumat")*IFERROR(VLOOKUP($C17,DATA_JAM_PELAJARAN!$C:$K,7,0),0)+(ABSENSI!D$3:AQ$3="Sabtu")*IFERROR(VLOOKUP($C17,DATA_JAM_PELAJARAN!$C:$K,8,0),0))) -> 0 | H17: =SUMPRODUCT((ABSENSI!D14:AQ14="Izin")*((ABSENSI!D$3:AQ$3="Senin")*IFERROR(VLOOKUP($C17,DATA_JAM_PELAJARAN!$C:$K,3,0),0)+(ABSENSI!D$3:AQ$3="Selasa")*IFERROR(VLOOKUP($C17,DATA_JAM_PELAJARAN!$C:$K,4,0),0)+(ABSENSI!D$3:AQ$3="Rabu")*IFERROR(VLOOKUP($C17,DATA_JAM_PELAJARAN!$C:$K,5,0),0)+(ABSENSI!D$3:AQ$3="Kamis")*IFERROR(VLOOKUP($C17,DATA_JAM_PELAJARAN!$C:$K,6,0),0)+(ABSENSI!D$3:AQ$3="Jumat")*IFERROR(VLOOKUP($C17,DATA_JAM_PELAJARAN!$C:$K,7,0),0)+(ABSENSI!D$3:AQ$3="Sabtu")*IFERROR(VLOOKUP($C17,DATA_JAM_PELAJARAN!$C:$K,8,0),0))) -> 0 | I17: =SUMPRODUCT((ABSENSI!D14:AQ14="Tanpa Keterangan")*((ABSENSI!D$3:AQ$3="Senin")*IFERROR(VLOOKUP($C17,DATA_JAM_PELAJARAN!$C:$K,3,0),0)+(ABSENSI!D$3:AQ$3="Selasa")*IFERROR(VLOOKUP($C17,DATA_JAM_PELAJARAN!$C:$K,4,0),0)+(ABSENSI!D$3:AQ$3="Rabu")*IFERROR(VLOOKUP($C17,DATA_JAM_PELAJARAN!$C:$K,5,0),0)+(ABSENSI!D$3:AQ$3="Kamis")*IFERROR(VLOOKUP($C17,DATA_JAM_PELAJARAN!$C:$K,6,0),0)+(ABSENSI!D$3:AQ$3="Jumat")*IFERROR(VLOOKUP($C17,DATA_JAM_PELAJARAN!$C:$K,7,0),0)+(ABSENSI!D$3:AQ$3="Sabtu")*IFERROR(VLOOKUP($C17,DATA_JAM_PELAJARAN!$C:$K,8,0),0))) -> 0 | J17: =SUM(G17:I17) -> 0 | K17: =COUNTIF(ABSENSI!D14:AQ14,"Mengajar") -> 16 | L17: =COUNTIF(ABSENSI!D14:AQ14,"Sakit") -> 0 | M17: =COUNTIF(ABSENSI!D14:AQ14,"Izin") -> 0 | N17: =COUNTIF(ABSENSI!D14:AQ14,"Tanpa Keterangan") -> 0 | O17: =IFERROR(F17/E17,0) -> 0.83116883 | P17: =SUMPRODUCT((ABSENSI!D$3:AQ$3="Senin")*(IFERROR(VLOOKUP($C17,DATA_JAM_PELAJARAN!$C:$K,3,0),0)>0)+(ABSENSI!D$3:AQ$3="Selasa")*(IFERROR(VLOOKUP($C17,DATA_JAM_PELAJARAN!$C:$K,4,0),0)>0)+(ABSENSI!D$3:AQ$3="Rabu")*(IFERROR(VLOOKUP($C17,DATA_JAM_PELAJARAN!$C:$K,5,0),0)>0)+(ABSENSI!D$3:AQ$3="Kamis")*(IFERROR(VLOOKUP($C17,DATA_JAM_PELAJARAN!$C:$K,6,0),0)>0)+(ABSENSI!D$3:AQ$3="Jumat")*(IFERROR(VLOOKUP($C17,DATA_JAM_PELAJARAN!$C:$K,7,0),0)>0)+(ABSENSI!D$3:AQ$3="Sabtu")*(IFERROR(VLOOKUP($C17,DATA_JAM_PELAJARAN!$C:$K,8,0),0)>0)) -> 19
B18: 12 | C18: Ahmad Yusup | D18: TIK | E18: =SUMPRODUCT((ABSENSI!D$3:AQ$3="Senin")*IFERROR(VLOOKUP($C18,DATA_JAM_PELAJARAN!$C:$K,3,0),0)+(ABSENSI!D$3:AQ$3="Selasa")*IFERROR(VLOOKUP($C18,DATA_JAM_PELAJARAN!$C:$K,4,0),0)+(ABSENSI!D$3:AQ$3="Rabu")*IFERROR(VLOOKUP($C18,DATA_JAM_PELAJARAN!$C:$K,5,0),0)+(ABSENSI!D$3:AQ$3="Kamis")*IFERROR(VLOOKUP($C18,DATA_JAM_PELAJARAN!$C:$K,6,0),0)+(ABSENSI!D$3:AQ$3="Jumat")*IFERROR(VLOOKUP($C18,DATA_JAM_PELAJARAN!$C:$K,7,0),0)+(ABSENSI!D$3:AQ$3="Sabtu")*IFERROR(VLOOKUP($C18,DATA_JAM_PELAJARAN!$C:$K,8,0),0)) -> 66 | F18: =SUMPRODUCT((ABSENSI!D15:AQ15="Mengajar")*((ABSENSI!D$3:AQ$3="Senin")*IFERROR(VLOOKUP($C18,DATA_JAM_PELAJARAN!$C:$K,3,0),0)+(ABSENSI!D$3:AQ$3="Selasa")*IFERROR(VLOOKUP($C18,DATA_JAM_PELAJARAN!$C:$K,4,0),0)+(ABSENSI!D$3:AQ$3="Rabu")*IFERROR(VLOOKUP($C18,DATA_JAM_PELAJARAN!$C:$K,5,0),0)+(ABSENSI!D$3:AQ$3="Kamis")*IFERROR(VLOOKUP($C18,DATA_JAM_PELAJARAN!$C:$K,6,0),0)+(ABSENSI!D$3:AQ$3="Jumat")*IFERROR(VLOOKUP($C18,DATA_JAM_PELAJARAN!$C:$K,7,0),0)+(ABSENSI!D$3:AQ$3="Sabtu")*IFERROR(VLOOKUP($C18,DATA_JAM_PELAJARAN!$C:$K,8,0),0))) -> 56 | G18: =SUMPRODUCT((ABSENSI!D15:AQ15="Sakit")*((ABSENSI!D$3:AQ$3="Senin")*IFERROR(VLOOKUP($C18,DATA_JAM_PELAJARAN!$C:$K,3,0),0)+(ABSENSI!D$3:AQ$3="Selasa")*IFERROR(VLOOKUP($C18,DATA_JAM_PELAJARAN!$C:$K,4,0),0)+(ABSENSI!D$3:AQ$3="Rabu")*IFERROR(VLOOKUP($C18,DATA_JAM_PELAJARAN!$C:$K,5,0),0)+(ABSENSI!D$3:AQ$3="Kamis")*IFERROR(VLOOKUP($C18,DATA_JAM_PELAJARAN!$C:$K,6,0),0)+(ABSENSI!D$3:AQ$3="Jumat")*IFERROR(VLOOKUP($C18,DATA_JAM_PELAJARAN!$C:$K,7,0),0)+(ABSENSI!D$3:AQ$3="Sabtu")*IFERROR(VLOOKUP($C18,DATA_JAM_PELAJARAN!$C:$K,8,0),0))) -> 0 | H18: =SUMPRODUCT((ABSENSI!D15:AQ15="Izin")*((ABSENSI!D$3:AQ$3="Senin")*IFERROR(VLOOKUP($C18,DATA_JAM_PELAJARAN!$C:$K,3,0),0)+(ABSENSI!D$3:AQ$3="Selasa")*IFERROR(VLOOKUP($C18,DATA_JAM_PELAJARAN!$C:$K,4,0),0)+(ABSENSI!D$3:AQ$3="Rabu")*IFERROR(VLOOKUP($C18,DATA_JAM_PELAJARAN!$C:$K,5,0),0)+(ABSENSI!D$3:AQ$3="Kamis")*IFERROR(VLOOKUP($C18,DATA_JAM_PELAJARAN!$C:$K,6,0),0)+(ABSENSI!D$3:AQ$3="Jumat")*IFERROR(VLOOKUP($C18,DATA_JAM_PELAJARAN!$C:$K,7,0),0)+(ABSENSI!D$3:AQ$3="Sabtu")*IFERROR(VLOOKUP($C18,DATA_JAM_PELAJARAN!$C:$K,8,0),0))) -> 0 | I18: =SUMPRODUCT((ABSENSI!D15:AQ15="Tanpa Keterangan")*((ABSENSI!D$3:AQ$3="Senin")*IFERROR(VLOOKUP($C18,DATA_JAM_PELAJARAN!$C:$K,3,0),0)+(ABSENSI!D$3:AQ$3="Selasa")*IFERROR(VLOOKUP($C18,DATA_JAM_PELAJARAN!$C:$K,4,0),0)+(ABSENSI!D$3:AQ$3="Rabu")*IFERROR(VLOOKUP($C18,DATA_JAM_PELAJARAN!$C:$K,5,0),0)+(ABSENSI!D$3:AQ$3="Kamis")*IFERROR(VLOOKUP($C18,DATA_JAM_PELAJARAN!$C:$K,6,0),0)+(ABSENSI!D$3:AQ$3="Jumat")*IFERROR(VLOOKUP($C18,DATA_JAM_PELAJARAN!$C:$K,7,0),0)+(ABSENSI!D$3:AQ$3="Sabtu")*IFERROR(VLOOKUP($C18,DATA_JAM_PELAJARAN!$C:$K,8,0),0))) -> 0 | J18: =SUM(G18:I18) -> 0 | K18: =COUNTIF(ABSENSI!D15:AQ15,"Mengajar") -> 16 | L18: =COUNTIF(ABSENSI!D15:AQ15,"Sakit") -> 0 | M18: =COUNTIF(ABSENSI!D15:AQ15,"Izin") -> 0 | N18: =COUNTIF(ABSENSI!D15:AQ15,"Tanpa Keterangan") -> 0 | O18: =IFERROR(F18/E18,0) -> 0.84848485 | P18: =SUMPRODUCT((ABSENSI!D$3:AQ$3="Senin")*(IFERROR(VLOOKUP($C18,DATA_JAM_PELAJARAN!$C:$K,3,0),0)>0)+(ABSENSI!D$3:AQ$3="Selasa")*(IFERROR(VLOOKUP($C18,DATA_JAM_PELAJARAN!$C:$K,4,0),0)>0)+(ABSENSI!D$3:AQ$3="Rabu")*(IFERROR(VLOOKUP($C18,DATA_JAM_PELAJARAN!$C:$K,5,0),0)>0)+(ABSENSI!D$3:AQ$3="Kamis")*(IFERROR(VLOOKUP($C18,DATA_JAM_PELAJARAN!$C:$K,6,0),0)>0)+(ABSENSI!D$3:AQ$3="Jumat")*(IFERROR(VLOOKUP($C18,DATA_JAM_PELAJARAN!$C:$K,7,0),0)>0)+(ABSENSI!D$3:AQ$3="Sabtu")*(IFERROR(VLOOKUP($C18,DATA_JAM_PELAJARAN!$C:$K,8,0),0)>0)) -> 19
